Workbook

Sheet Project Report
A1: Year | B1: Project Name | C1: Unit | D1: Backlog | E1: โอนแล้ว | F1: รวมลูกค้า Origin | G1: ลูกค้า Wyde | H1: %ขายWYDE | I1: มูลค่าPackage | J1: Backlog | K1: Book | L1: รายได้ Per/Bill | N1: ลค.ต้องติดตามต่อ | O1: FC | P1: Rev./BIll | Q1: Target Rev.
A2: 0 | B2: Origin Plug&Play Srinakarin | N2: (โอนแล้วยังไม่ซื้อWYDE) | O2: 0.8
A3: 2025 | B3: The Origin Praksa | C3: 827 | D3: 237 | E3: 216 | F3: =E3+D3 -> 453 | G3: 122 | H3: =G3/F3 -> 0.26931567 | I3: =SUM('ลค. Event'!E157:E237) -> 0 | L3: =I3/G3 -> 0 | N3: 117 | O3: =N3*O2 -> 93.6 | P3: 40000 | Q3: =O3*P3 -> 3744000
A4: 2025 | B4: The Origin Phahol 57 | C4: 432 | D4: 116 | E4: 168 | F4: =E4+D4 -> 284 | G4: 23 | H4: =G4/F4 -> 0.080985915 | I4: =SUM('ลค. Event'!E133:E155) -> 0 | L4: =I4/G4 -> 0 | N4: 263 | O4: =N4*O2 -> 210.4 | P4: 80000 | Q4: =O4*P4 -> 16832000
A5: 2025 | B5: Origin play Bangsaen | C5: 494 | D5: 87 | E5: 299 | F5: =E5+D5 -> 386 | G5: 34 | H5: =G5/F5 -> 0.088082902 | I5: =SUM('ลค. Event'!E2:E9) -> 0 | L5: =I5/G5 -> 0 | N5: 270 | O5: =N5*O2 -> 216 | P5: 80000 | Q5: =O5*P5 -> 17280000
A6: 2025 | B6: Origin play Bangkhunnon | C6: 477 | D6: 198 | E6: 255 | F6: =E6+D6 -> 453 | G6: 47 | H6: =G6/F6 -> 0.10375276 | I6: =SUM(#REF!) -> #REF! | L6: =I6/G6 -> #REF! | N6: ='ตามต่อบางขุนนท์'!B219 -> 215 | O6: =N6*O2 -> 172 | P6: 100000 | Q6: =O6*P6 -> 17200000
A7: 2025 | B7: The Origin Kathu-Patong | C7: 624 | D7: 325 | E7: 245 | F7: =E7+D7 -> 570 | G7: 30 | H7: =G7/F7 -> 0.052631579 | I7: =SUM('ลค. Event'!E103:E132) -> 0 | L7: =I7/G7 -> 0 | N7: 310 | O7: =N7*O2 -> 248 | P7: 120000 | Q7: =O7*P7 -> 29760000
A8: 2025 | B8: The Origin Bangkae | C8: 1485 | D8: 506 | E8: 212 | F8: =E8+D8 -> 718 | G8: 29 | H8: =G8/F8 -> 0.040389972 | I8: =SUM('ลค. Event'!E74:E102) -> 0 | L8: =I8/G8 -> 0 | N8: ='ติดตามต่อบางแค'!A191 -> 189 | O8: =N8*O2 -> 151.2 | P8: 150000 | Q8: =O8*P8 -> 22680000
A9: 2026 | B9: Origin Place Khonkaen | C9: 442 | D9: 167 | E9: 82 | F9: =E9+D9 -> 249 | G9: 17 | H9: =G9/F9 -> 0.068273092 | I9: =SUM(#REF!) -> #REF! | L9: =I9/G9 -> #REF! | N9: 268 | O9: =N9*O2 -> 214.4 | P9: 30000 | Q9: =O9*P9 -> 6432000
A10: 2026 | B10: So Origin Siriraj | C10: 256 | D10: 246 | E10: 0 | F10: =D10 -> 246 | G10: 22 | H10: =G10/F10 -> 0.089430894 | I10: =SUM('ลค. Event'!E239:E260) -> 0 | L10: =I10/G10 -> 0 | N10: =F10-G10 -> 224 | O10: =N10*O2 -> 179.2 | P10: 200000 | Q10: =O10*P10 -> 35840000 | R10: *ตามจากกลุมลูกค้าBACKLOG
A11: 2026 | B11: Origin Place Petkasem | C11: 353 | D11: 353 | E11: 0 | F11: =D11 -> 353 | G11: 28 | H11: =G11/F11 -> 0.079320113 | I11: 147000 | N11: =F11-G11 -> 325 | O11: =N11*O2 -> 260 | P11: 150000 | Q11: =O11*P11 -> 39000000
A12: 2026 | B12: So Origin Bangtao Beach | C12: 545 | D12: 326 | E12: 0 | F12: =D12 -> 326
A13: 2026 | B13: The Origin Center Phuket | C13: 701 | D13: 366 | E13: 0 | F13: =D13 -> 366
A14: 2026 | B14: The Origin Setthabut Station | C14: 530 | D14: 271 | E14: 0 | F14: =D14 -> 271
A15: 2026 | B15: Origin Thonglor world - IP | C15: 795 | D15: 332 | E15: 0 | F15: =D15 -> 332
C16: =SUM(C2:C15) -> 7961 | D16: =SUM(D3:D15) -> 3530 | E16: =SUM(E3:E15) -> 1477 | F16: =SUM(F3:F15) -> 5007 | G16: =SUM(G3:G15) -> 352 | H16: =G16/F16 -> 0.070301578 | I16: =SUM(I2:I15) -> #REF! | N16: =SUM(N3:N15) -> 2181 | O16: =SUM(O3:O15) -> 1744.8 | Q16: =SUM(Q3:Q15) -> 188768000
C19: พี่อ้อม | D19: =D11+D12+D13+D14+D7 -> 1641 | E19: ห้อง | N19: พี่เจี๊ยบ | O19: =N3+N4+N5+N6+N8+N9+N10 -> 1546 | P19: ห้อง
C20: คาดยอดขาย | D20: 200000000 | N20: คาดยอดขาย | O20: 350000000
D21: =D20/D19 -> 121876.9 | E21: บ/ห้อง | O21: =O20/O19 -> 226390.69 | P21: บ/ห้อง
C23: KPI | D23: BOOKING | N23: KPI | O23: BOOKING
C24: 1 | D24: =D20 -> 200000000 | N24: 1 | O24: =O20 -> 350000000
C25: 0.8 | D25: =D24*C25 -> 160000000 | N25: 0.8 | O25: =O24*N25 -> 280000000
C26: 0.5 | D26: =C26*D24 -> 100000000 | N26: 0.5 | O26: =N26*O24 -> 175000000
C28: Current | D28: 12000000 | E28: =D28/D20 -> 0.06 | N28: Current | O28: 38000000 | P28: =O28/O20 -> 0.10857143
C29: ทำเพิ่ม | D29: =D20-D28 -> 188000000 | N29: ทำเพิ่ม | O29: =O20-O28 -> 312000000
C32: มีเป้าหมายแล้ว ทำ กลยุทธ และ ทำKPI วัดผม
C33: 1.จัดทำSOP การบริหารจัดการกลยุทธการขาย >>> มีนโยบาย มีกลยุทธ แล้ว มีKPI /// การวางการขาย ในเล่มจะประกอบด้วย สร้างใหม่ รับนโยบายมา กลยุทธ ออกมาเป็น KPI แล้ววางแผนการขาย ยังไง เป็น 1 เล่ม
C34: (เอกสารSUBMIT KPI) ต้องคุยเรื่องทิศทางในการขาย กับProject Asia ว่ากลยุทธการขาย จะยังไง ไปในมุม Consult วางStructure คน ราคา งานจาก Project asia ไปเป็นConsult แนะนำ interior ให้Owner กับ อีกอัน แนวทางการหาลูกค้าของเรา มี กี่แนวทาง วิธีการบังไงบ้าง วัดผลยังไ
C35: เป็น Consult Interior ในหัวของProject Asia // หรือ เป็นบริษัทPartner ที่แนะนำ PJA แนะนำงาน
C36: 2.จัดทำ SOP การวางแผนการตลาด เขียนตามสิ่งที่ทำ เอกสารผู้มีอำนาจ อนุมัติ กรอบวงเงินMKT มีแบบฟอร์มเอกสาร ขั้นตอนยังไง ให้เขียน ไป เช่น จะไปออกอีเว้นต์ ต้องทำอะไรบ้าง ทำแพ๊กเกจขาย Head sales รับผิดชอบ ราคาขาย โปรโมชั่น ในอีเว้นต์ ใคร อนุมัติ ใครเป็นคนติดต่อสถานที่ ใครเป็นคนสรุปผลทางการตลาด เกิดpipelineไหมใน การขายนี้ ให้Claude คิด แล้ว เขียนเป็นSOP ออกมาให้ // เขียนข้อกำหนดรองรับในการให้ส่วนลดและโปรโมชั่น ส่วนลดต้องทำยังไง โปรโมชั่นต้องทำยังไง Deposit 5000 /10000 ต้องทำยังไง เช่น ขออนุมัติ manager ก็เขียนให้ละเอียด
C37: 3.ทำแบบฟอร์มการขึ้นทะเบียนลูกค้า (มีอยู่แล้ว)
C38: 4.ทำSOP การจัดทำสัญญาบริการ สำหรับงานที่มีมูลค่าสูง
C39: 5.ทำSOP การจัดการข้อร้องเรียนของลูกค้า (ใครเป็นคนรับข้อร้องเรียนลูกค้า เก็บสถิติยังไง )
C41: 6.มาตรฐานการทำงาน ว่าทำงานบนหลักเกณฑ์ อะไร เช่น มีวิศวกรควบคุม // เอกสารตรวจงาน ใช้มตรฐานอะไรมา ตรวจงานให้ลูกค้า // ข้อกำหนด ของ การดำเนิน รู้ว่าProcess ที่ทำ มีอะไรเป็นตัวกำหนด มาตรฐานบ้าง การตรวจงานQC reference จากอะไร
C42: Project spec standard // มาตรฐานวิชาชีพวิศวะกรรมในประเทศ // มาตรฐานสำหรับงานเฉพาะทาง // มาตรฐานค่าความคลาดเคลื่อนที่ยอมรับได้ // เช่น กระเบื้อง เคาะแล้ว ต้อง ไม่ป่อง เกิน 20% // คนที่ เดินงานระบบไฟ ได้ ต้องมีใบประกอบวิชาชีพ

Sheet ชีต26

Sheet KPI
B1: Sales Manager : Jeab | K1: Sales Manager : Aom
A2: Year | B2: Project | C2: Sales | D2: Target | E2: Actual | F2: Backlog | G2: Book | H2: New Case | J2: Year | K2: Project | L2: Sales | M2: Target | N2: Actual | O2: Backlog | P2: Book | Q2: New Case
B3: Park Origin Thonglor | C3: Ying | D3: 20 | F3: 1 | J3: 2026 | K3: The Origin Kathu-Patong | L3: Pon | M3: 100 | O3: 13 | P3: 0.8 | Q3: 8
B4: Park Origin Ratchathewi | C4: Pang | D4: 20 | F4: 4 | J4: 2026 | K4: SO Origin Bangtao Beach | L4: Pon | M4: 50
A5: 2024 | B5: Origin Plug&Play Sirindhorn Station | C5: Ying | D5: 15 | J5: 2026 | K5: The Origin Center-Phuket | L5: Pon | M5: 50
B6: Park 24 Juristic Person 1 | C6: Josh | D6: 5 | J6: 2026 | K6: ฺB2B | L6: Aun
B7: Origin Plug&Play Nonthaburi Station | C7: Josh | D7: 2
A8: 2024 | B8: Origin Plug&Play E22 Station | C8: Pang | D8: 2
B9: Park Origin Phayathai | C9: Hack | D9: 2
B10: Park origin Chula Samyan | C10: Hack | D10: 10
A11: 2024 | B11: The Origin Campus Khonkaen | C11: Josh | D11: 1 | F11: 0.26
A12: 2024 | B12: Knighsbridge Space Raman4 | C12: Ying | D12: 1 | F12: 0.7
A13: 2025 | B13: So Origin Kaset Interchange | C13: Ying | D13: 5
A14: 2025 | B14: Origin Plug&Play Srinakarin | C14: Ying | D14: 10
A15: 2025 | B15: So Phahol 69 Station | C15: Josh | D15: 10
A16: 2025 | B16: The Origin Sukhumvit Praksa | C16: Pang | D16: =10+4.5 -> 14.5 | E16: 1.45 | F16: 1.97 | G16: 1.68
A17: 2025 | B17: Origin Place Bangna | C17: Ying | D17: =21+1 -> 22 | E17: 0.42 | F17: 0.5 | G17: 0.3
A18: 2025 | B18: Origin Play Bangsaen | C18: Pang | D18: =21+3 -> 24 | E18: 0.27 | F18: 1.62 | G18: 1.38
A19: 2025 | B19: The Origin Bangkae | C19: Hack | D19: =28+2.6 -> 30.6 | E19: =Sumifs('ลค. Event'!$K:$K,'ลค. Event'!$I:$I,B19,'ลค. Event'!$U:$U,"ส่งมอบแล้ว") -> 0 | F19: 0.11 | G19: 2.52
A20: 2025 | B20: Origin Play Bangkhunnon | C20: Hack | D20: =21+7.2 -> 28.2 | E20: 0.47 | F20: 0.83 | G20: 7.24
A21: 2025 | B21: The Origin Phahol 57 | C21: Josh | D21: =21+1.2 -> 22.2 | E21: 1.06 | F21: 0.03 | G21: 0.29
A22: 202ุ6 | B22: Origin Place Khon Kaen-Kanlapaphruek | C22: Josh | D22: =10.1+2.4 -> 12.5 | G22: 2.73
A23: 202ุ6 | B23: SO Origin Siriraj | C23: Ying | D23: =45+6 -> 51 | G23: 6.36
A24: 2026 | B24: The Origin Setthabut | C24: Josh | D24: 10
A25: 2026 | B25: Origin Place Petchkasem | C25: Pang | D25: 20
A26: 2026 | B26: Thonglor World-IP | C26: Ying
A27: 2026 | B27: โครงการนอกเครือ Origin | C27: Hack | D27: 2
A28: 2026 | B28: โครงการนอกเครือ Origin | C28: Josh | D28: 10
C29: Sum (MB.) | D29: =Sum(D3:D28) -> 350 | E29: =Sum(E3:E28) -> 3.67 | F29: =Sum(F3:F28) -> 11.02 | G29: =Sum(G3:G28) -> 22.5 | H29: =Sum(H3:H28) -> 0 | L29: Sum (MB.) | M29: =Sum(M3:M28) -> 200 | O29: =Sum(O3:O28) -> 13 | P29: =Sum(P3:P28) -> 0.8 | Q29: =Sum(Q3:Q28) -> 8
C31: Manager | D31: Target | E31: Actual | F31: Backlog | G31: Book | H31: New Case | L31: Manager | M31: Target | N31: Actual | O31: Backlog | P31: Book | Q31: New Case
B32: Target 350 MB | C32: Jeab | D32: =Sum(D34:D37) -> 350 | E32: =Sum(E34:E37) -> 3.67 | F32: =Sum(F34:F37) -> 11.02 | G32: =Sum(G34:G37) -> 22.5 | H32: =Sum(H34:H37) -> 0 | L32: Aom | M32: =Sum(M34:M37) -> 200 | O32: =Sum(O34:O37) -> 29.2 | P32: =Sum(P34:P37) -> 0.8 | Q32: =Sum(Q34:Q37) -> 10
C33: Sales | D33: Target | E33: Actual | F33: Backlog | G33: Book | H33: New Case | L33: Sales | M33: Target | N33: Actual | O33: Backlog | P33: Book | Q33: New Case
B34: Target 110 MB | C34: Ying | D34: =Sumifs(D3:D28,C3:C28,"Ying") -> 124 | E34: =Sumifs(E3:E28,C3:C28,"Ying") -> 0.42 | F34: =Sumifs(F3:F28,C3:C28,"Ying") -> 2.2 | G34: =Sumifs(G3:G28,C3:C28,"Ying") -> 6.66 | L34: Pon | M34: 100 | O34: 13 | P34: 0.8 | Q34: 8
B35: Target 80 MB | C35: Pang | D35: =Sumifs(D3:D28,C3:C28,"Pang") -> 80.5 | E35: =Sumifs(E3:E28,C3:C28,C35) -> 1.72 | F35: =Sumifs(F3:F28,C3:C28,"Pang") -> 7.59 | G35: =Sumifs(G3:G28,C3:C28,"Pang") -> 3.06 | L35: Aun | M35: 100 | O35: 16.2 | P35: - | Q35: 2
B36: Target 80 MB | C36: Josh | D36: =Sumifs(D3:D28,C3:C28,"Josh") -> 72.7 | E36: =Sumifs(E4:E29,C4:C29,C36) -> 1.06 | F36: =Sumifs(F3:F28,C3:C28,"Josh") -> 0.29 | G36: =Sumifs(G3:G28,C3:C28,"Josh") -> 3.02
B37: Target 80 MB | C37: Hack | D37: =Sumifs(D3:D28,C3:C28,"Hack") -> 72.8 | E37: =Sumifs(E5:E30,C5:C30,C37) -> 0.47 | F37: =Sumifs(F3:F28,C3:C28,"Hack") -> 0.94 | G37: =Sumifs(G3:G28,C3:C28,"Hack") -> 9.76
A41: 2025 | B41: The Origin Sukhumvit Praksa | C41: Pang | D41: =10+4.5 -> 14.5 | E41: =Sumifs('ลค. Event'!$K:$K,'ลค. Event'!$I:$I,B16,'ลค. Event'!$U:$U,"ส่งมอบแล้ว") -> 1459084.1 | F41: =SUMIFS('ลค. Event'!K:K,'ลค. Event'!I:I,B41,'ลค. Event'!R:R,"50%")+SUMIFS('ลค. Event'!K:K,'ลค. Event'!I:I,B41,'ลค. Event'!R:R,"100%") -> 1975400 | G41: =Sumifs('ลค. Event'!$K:$K,'ลค. Event'!$I:$I,B41,'ลค. Event'!$R:$R,"จองสิทธิ์") -> 1688860
A42: 2025 | B42: Origin Place Bangna | C42: Ying | D42: =21+1 -> 22 | E42: =Sumifs('ลค. Event'!$K:$K,'ลค. Event'!$I:$I,B42,'ลค. Event'!$U:$U,"ส่งมอบแล้ว") -> 429943.93 | F42: =SUMIFS('ลค. Event'!K:K,'ลค. Event'!I:I,B42,'ลค. Event'!R:R,"50%")+SUMIFS('ลค. Event'!K:K,'ลค. Event'!I:I,B42,'ลค. Event'!R:R,"100%") -> 501100 | G42: =Sumifs('ลค. Event'!$K:$K,'ลค. Event'!$I:$I,B42,'ลค. Event'!$R:$R,"จองสิทธิ์") -> 319400
A43: 2025 | B43: Origin Play Bangsaen | C43: Pang | D43: =21+3 -> 24 | E43: =Sumifs('ลค. Event'!$K:$K,'ลค. Event'!$I:$I,B43,'ลค. Event'!$U:$U,"ส่งมอบแล้ว") -> 277289.72 | F43: =SUMIFS('ลค. Event'!K:K,'ลค. Event'!I:I,B43,'ลค. Event'!R:R,"50%")+SUMIFS('ลค. Event'!K:K,'ลค. Event'!I:I,B43,'ลค. Event'!R:R,"100%") -> 1621300 | G43: =Sumifs('ลค. Event'!$K:$K,'ลค. Event'!$I:$I,B43,'ลค. Event'!$R:$R,"จองสิทธิ์") -> 1380210
A44: 2025 | B44: The Origin Bangkae | C44: Hack | D44: =28+2.6 -> 30.6 | E44: =Sumifs('ลค. Event'!$K:$K,'ลค. Event'!$I:$I,B44,'ลค. Event'!$U:$U,"ส่งมอบแล้ว") -> 0 | F44: =SUMIFS('ลค. Event'!K:K,'ลค. Event'!I:I,B44,'ลค. Event'!R:R,"50%")+SUMIFS('ลค. Event'!K:K,'ลค. Event'!I:I,B44,'ลค. Event'!R:R,"100%") -> 115200 | G44: =Sumifs('ลค. Event'!$K:$K,'ลค. Event'!$I:$I,B44,'ลค. Event'!$R:$R,"จองสิทธิ์") -> 2526940
...

Sheet Action plan 30MBMonth
B2: Sales / Target | C2: Year | D2: Quarter | E2: Month | F2: Week | G2: day
B3: Jeab | C3: =SUM(C4:C7) -> 350 | D3: =C3/4 -> 87.5 | E3: =D3/3 -> 29.166667 | F3: =E3/4 -> 7.2916667 | G3: =F3/6 -> 1.2152778
B4: Ying | C4: 120 | D4: =C4/4 -> 30 | E4: =D4/3 -> 10 | F4: =E4/4 -> 2.5 | G4: =F4/6 -> 0.41666667
B5: Pang | C5: 80 | D5: =C5/4 -> 20 | E5: =D5/3 -> 6.6666667 | F5: =E5/4 -> 1.6666667 | G5: =F5/6 -> 0.27777778
B6: Josh | C6: 75 | D6: =C6/4 -> 18.75 | E6: =D6/3 -> 6.25 | F6: =E6/4 -> 1.5625 | G6: =F6/6 -> 0.26041667
B7: Hack | C7: 75 | D7: =C7/4 -> 18.75 | E7: =D7/3 -> 6.25 | F7: =E7/4 -> 1.5625 | G7: =F7/6 -> 0.26041667
B9: Action plan / Day (Daily Report)
B10: Sales : Name
B11: Target : 0.42 MB
B12: Activity | C12: ที่มา | D12: Action | E12: เป้าหมาย | F12: ทำแล้ว | G12: ขาด | H12: ผล | I12: ยอดขาย | J12: Retio | K12: Remark
B13: Online Lead | C13: Facebook/IG | D13: Chat&Call | E13: 5 | F13: 0 | G13: =E13-F13 -> 5
B14: Offline Lead | C14: Wyde Data | D14: Call | E14: 10 | F14: 0 | G14: =E14-F14 -> 10
C15: Line OA | D15: Chat&Call | E15: 5 | F15: 0 | G15: =E15-F15 -> 5
F16: 0 | G16: =E16-F16 -> 0
F17: 0 | G17: =E17-F17 -> 0
F18: 0 | G18: =E18-F18 -> 0
B20: Sales / Target | C20: Year | D20: Quarter | E20: Month | F20: Week | G20: day
B21: Aom | C21: =SUM(C22:C23) -> 200 | D21: =C21/4 -> 50 | E21: =D21/3 -> 16.666667 | F21: =E21/4 -> 4.1666667 | G21: =F21/6 -> 0.69444444
B22: Pon | C22: 100 | D22: =C22/4 -> 25 | E22: =D22/3 -> 8.3333333 | F22: =E22/4 -> 2.0833333 | G22: =F22/6 -> 0.34722222
B23: Aun | C23: 100 | D23: =C23/4 -> 25 | E23: =D23/3 -> 8.3333333 | F23: =E23/4 -> 2.0833333 | G23: =F23/6 -> 0.34722222

Sheet KPI ทีมพี่เจี๊ยบ
A1: Month | B1: Week | C1: Salesperson | D1: Target_Amount | E1: Actual_Sales | F1: Achievement_Rate | G1: Notes
A2: May | B2: Week 1 | C2: YING | D2: 1600000 | E2: 0 | F2: 0
A3: May | B3: Week 1 | C3: PANG | D3: 1600000 | E3: 0 | F3: 0
A4: May | B4: Week 1 | C4: JOSH | D4: 1600000 | E4: 0 | F4: 0
A5: May | B5: Week 1 | C5: HACK | D5: 1600000 | E5: 0 | F5: 0
A6: May | B6: Week 2 | C6: YING | D6: 2000000 | E6: 0 | F6: 0
A7: May | B7: Week 2 | C7: PANG | D7: 2000000 | E7: 0 | F7: 0
A8: May | B8: Week 2 | C8: JOSH | D8: 2000000 | E8: 0 | F8: 0
A9: May | B9: Week 2 | C9: HACK | D9: 2000000 | E9: 0 | F9: 0
A10: May | B10: Week 3 | C10: YING | D10: 2400000 | E10: 0 | F10: 0
A11: May | B11: Week 3 | C11: PANG | D11: 2400000 | E11: 0 | F11: 0
A12: May | B12: Week 3 | C12: JOSH | D12: 2400000 | E12: 0 | F12: 0
A13: May | B13: Week 3 | C13: HACK | D13: 2400000 | E13: 0 | F13: 0
... A129: December | B129: Week 4 | C129: HACK | D129: 2750000 | E129: 0 | F129: 0

Sheet Area Assignment
A1: Area-Project | B1: Head | C1: Sales name | D1: Position | E1: Assign
A2: Phuket
A3: The Origin Kathu-Patong | B3: Aom | C3: pon | D3: Senior Project Interior Designer | E3: งานขาย(ลูกค้า Thai +Online ต่างชาติ) + เอกสาร (ลูกค้าไทย +ต่างชาติ) +Designer Brief
A4: SO Origin Bangtao Beach | B4: Aom | C4: pon | D4: Senior Project Interior Designer | E4: งานขาย(ลูกค้า Thai +Online ต่างชาติ) + เอกสาร (ลูกค้าไทย +ต่างชาติ) +Designer Brief
A5: The Origin Center-Phuket | B5: Aom | C5: pon | D5: Senior Project Interior Designer | E5: งานขาย(ลูกค้า Thai +Online ต่างชาติ) + เอกสาร (ลูกค้าไทย +ต่างชาติ) +Designer Brief
A6: Khonkaen
A7: Origin Place Khonkaen | B7: Jeab | C7: Josh | D7: Sales & Marketing Executive | E7: งานขาย(ลูกค้าไทย +Online + เอกสาร +Designer Brief
A8: The Origin Campus Khonkaen | B8: Jeab | C8: Josh | D8: Sales & Marketing Executive | E8: งานขาย(ลูกค้าไทย +Online + เอกสาร +Designer Brief
A9: Nonthaburi
A10: Origin Plug&Play Nonthaburi Station | B10: Jeab | C10: Josh | D10: Sales & Marketing Executive | E10: งานขาย(ลูกค้าไทย +Visit site + เอกสาร +Designer Brief
A11: Samutprakarn
A12: The Origin Praksa | B12: Jeab | C12: Pang | D12: Sales & Marketing Executive | E12: งานขาย(ลูกค้าไทย +Visit site) + เอกสาร +Designer Brief
A13: Origin Plug&Play Srinakarin | B13: Jeab | C13: Ying | D13: Senior Sales & Marketing Executive | E13: งานขาย( (ลูกค้าไทย+ต่างชาติ+Visit site) + เอกสาร +Designer Brief
A14: Origin Plug&Play E22 Station | B14: Jeab | C14: Pang | D14: Sales & Marketing Executive | E14: งานขาย(ลูกค้าไทย +Visit site) + เอกสาร +Designer Brief
A15: The Origin E22 Station | B15: Jeab | C15: Pang | D15: Sales & Marketing Executive | E15: งานขาย(ลูกค้าไทย +Visit site) + เอกสาร +Designer Brief
A16: Rayong
A17: Hampton Suite Rayong | B17: Jeab
A18: Chonburi
A19: Origin Play Bangsaen | B19: Jeab | C19: Pang | D19: Sales & Marketing Executive | E19: งานขาย(ลูกค้าไทย +Visit site) + เอกสาร +Designer Brief
A20: Brixton Campus Sriracha | B20: Jeab
A21: ฺBangkok - BKK
A22: Bangna
A23: Origin Place Bangna | B23: Jeab | C23: Ying | D23: Senior Sales & Marketing Executive | E23: งานขาย( (ลูกค้าไทย+ต่างชาติ+Visit site) + เอกสาร +Designer Brief
A24: Thonglor
A25: Thonglor World | B25: Aom | C25: Pon | D25: Senior Sales & Marketing Executive | E25: งานขาย(ลูกค้าOnline) + เอกสาร (ลูกค้าไทย +ต่างชาติ) +Designer Brief
A26: Park Origin Thonglor | B26: Jeab | C26: Ying | D26: Senior Sales & Marketing Executive | E26: งานขาย(Visit site) + เอกสาร (ลูกค้าไทย +ต่างชาติ) +Designer Brief
A27: Phaholyothin
A28: The Origin Phahol 57 | B28: Jeab | C28: Josh | D28: Sales & Marketing Executive | E28: งานขาย(ลูกค้าไทย +Visit site) + เอกสาร +Designer Brief
A29: SO Origin Phahol 69 | B29: Jeab | C29: Josh | D29: Sales & Marketing Executive | E29: งานขาย(ลูกค้าไทย +Visit site) + เอกสาร +Designer Brief
A30: Brixton Phahol 50 | B30: Jeab | C30: Josh | D30: Sales & Marketing Executive | E30: งานขาย(ลูกค้าไทย +Visit site) + เอกสาร +Designer Brief
A31: SO Origin Kaset-Interchange
A32: Pinklao
A33: SO Origin Siriraj | B33: Jeab | C33: Ying | D33: Senior Sales & Marketing Executive | E33: งานขาย(Visit site) + เอกสาร (ลูกค้าไทย +ต่างชาติ) +Designer Brief
A34: Origin Play Bangkhunnon | B34: Jeab | C34: Hack | D34: Sales & Marketing Executive | E34: งานขาย(ลูกค้าไทย +Visit site) + เอกสาร +Designer Brief
A35: Origin Plug&Play Sirinthorn | B35: Jeab | C35: Ying | D35: Senior Sales & Marketing Executive | E35: งานขาย(Visit site) + เอกสาร (ลูกค้าไทย +ต่างชาติ) +Designer Brief
A36: Ramkamheng
A37: Origin Plug&Play Ram103 | B37: Jeab | C37: Pang | D37: Sales & Marketing Executive | E37: งานขาย(ลูกค้าไทย +Visit site) + เอกสาร +Designer Brief
A38: Ramintra
A39: The Origin Setthabut | B39: Aom | C39: Pon | D39: Sales & Marketing Executive | E39: งานขาย(ลูกค้าไทย +Visit site) + เอกสาร +Designer Brief
A40: Origin Plug&play Ramintra | B40: Jeab | C40: Hack | D40: Sales & Marketing Executive | E40: งานขาย(ลูกค้าไทย +Visit site) + เอกสาร +Designer Brief
...

Sheet Booking
A1: ID | B1: วันที่บันทึก | C1: ประเภทลูกค้า | D1: ชื่อลูกค้า | E1: เบอร์ติดต่อ | F1: โครงการ | G1: หมายเลขห้อง | H1: Package ที่เลือก | I1: ราคาแพ็กเกจ | J1: ส่วนลด / Voucher | K1: ยอดสุทธิ | L1: เงินจองสิทธิ์ | M1: ช่องทางการชำระ | N1: หลักฐานการโอน | O1: พนักงานขาย | P1: สถานะการจอง

Sheet Daily Cash
A1: หัวตาราง (Column Header) | B1: ประเภทข้อมูล (Type ใน AppSheet) | C1: หมายเหตุ
A2: Cash ID | B2: Key
A3: วันที่ | B3: Date
A4: ประเภทรายการ | B4: Enum | C4: ตัวเลือก: รายรับ (จอง), รายรับ (อื่นๆ), รายจ่าย
A5: รายการ | B5: Text | C5: เช่น "รับเงินจอง คุณ..." หรือ "ค่าอุปกรณ์สำนักงาน"
A6: จำนวนเงิน | B6: Price
A7: ช่องทางเงิน | B7: Enum | C7: ตัวเลือก: บัญชีบริษัท, บัญชีต่างประเทศ, เงินสดหน้าร้าน
A8: Ref ID (ถ้ามี) | B8: Text | C8: สำหรับใส่ ID จากตาราง Booking มาโยงกัน

Sheet ลค. Event
A1: ปี-เดือน | B1: ปี | C1: เดือน | D1: PO Origin NO. | E1: SO | F1: ประเภทงาน | G1: วันที่รับยอด/PO | H1: ชื่อลูกค้า | I1: Project Name | J1: ห้อง | K1: Revenue(Ex.Vat) | L1: Revenue(Inc.Vat) | M1: ยอดโอน | N1: Voucher | O1: Cost | P1: Profit | Q1: GP% | R1: Working status | S1: Sale | T1: QC | U1: สถานะห้อง | V1: Finish Month | W1: วันที่ส่งมอบงาน | X1: หมายเหตุ | Y1: เดือนเบิกค่าคอมมิชชั่น | Z1: 0.012 | AA1: 0.0135 | AB1: 0.015 | AC1: 0.017 | AD1: 0.0185 | AE1: 0.022 | AF1: 0.025 | AG1: 0.0275 | AH1: 0.03 | AI1: 0.01 | AJ1: 0.015 | AK1: 0.02 | AL1: 500 | AM1: ปี-เดือน | AN1: ปี | AO1: เดือน | AP1: PO Origin NO. | AQ1: SO | AR1: ประเภทงาน | AS1: วันที่รับยอด/PO | AT1: ชื่อลูกค้า | AU1: Project Name | AV1: ห้อง | AW1: Revenue(Ex.Vat) | AX1: Revenue(Inc.Vat) | AY1: ยอดโอน | AZ1: Voucher | BA1: Cost | BB1: Profit | BC1: GP% | BD1: Working status | BE1: Sale | BF1: QC | BG1: สถานะห้อง | BH1: Finish Month | BI1: วันที่ส่งมอบงาน | BJ1: หมายเหตุ | BK1: เดือนเบิกค่าคอมมิชชั่น | BL1: 0.012 | BM1: 0.0135 | BN1: 0.015 | BO1: 0.017 | BP1: 0.0185 | BQ1: 0.022 | BR1: 0.025 | BS1: 0.0275 | BT1: 0.03 | BU1: 0.01 | BV1: 0.015 | BW1: 0.02 | BX1: 500
A2: 46023 | B2: 2026 | C2: 1 | F2: N-RPT/Event | G2: 46047 | H2: ศุภชัย ศรีกาญจนา | I2: Origin Campus khonkaen | J2: B408 | K2: 70000 | S2: อั๋น | U2: ดำเนินการ
A3: 46023 | B3: 2026 | C3: 1 | F3: N-RPT/Event | G3: 46047 | H3: กนกวรรณ ละม้าย | I3: Origin Campus khonkaen | J3: B427 | K3: 100000 | S3: อั๋น | U3: ดำเนินการ
A4: 46054 | B4: 2026 | C4: 2 | F4: N-RPT/Event | G4: 46068 | H4: ณภัสนันท์ ทองคำนุช | I4: Origin Campus khonkaen | J4: B304 | S4: อั๋น | U4: ดำเนินการ
A5: 46054 | B5: 2026 | C5: 2 | F5: N-RPT/Event | G5: 46068 | H5: ภัณฑิรา สิทธิการค้า | I5: Origin Campus khonkaen | J5: B321 | K5: 90000 | S5: อั๋น | U5: ดำเนินการ
A6: 45931 | B6: 2025 | C6: 36 | E6: WAG-SONO25-000698 | F6: N-RPT/Event | G6: 45949 | H6: คุณอานนท์ สมหล่อ | I6: Origin Place Bangna | J6: 510 | K6: 11401.87 | L6: 12200 | P6: 11401.87 | Q6: 1 | S6: หญิง | T6: อาม | U6: ส่งมอบแล้ว
A7: 45839 | B7: 2025 | C7: 46 | E7: WAG-SONO25-000925 | F7: N-RPT/Event | G7: 45850 | H7: บริษัท โปรเกรส แมคคานิค จำกัด | I7: Origin Place Bangna | J7: 540 | K7: 16261.68 | L7: 17400 | P7: 16261.68 | Q7: 1 | S7: หญิง | T7: นุ๊ก | U7: ส่งมอบแล้ว
A8: 45658 | B8: 2025 | C8: 37 | E8: WAG-SONO25-000729 | F8: N-RPT/Event | G8: 45668 | H8: คุณวริษฐา บรรพพงศ์ | I8: Origin Place Bangna | J8: 621 | K8: 79439.25 | L8: 85000 | P8: 79439.25 | Q8: 1 | S8: หญิง | T8: นุ๊ก | U8: ส่งมอบแล้ว
A9: 45870 | B9: 2025 | C9: 8 | F9: N-RPT/Event | G9: 45893 | H9: คุณศรายุทธ ศิวสิริการุณย์ | I9: Origin Place Bangna | J9: 640 | K9: 51100 | M9: 51100 | R9: 1 | S9: หญิง | T9: อาม | U9: ดำเนินการ
A10: 45962 | B10: 2025 | C10: 45 | E10: WAG-SONO25-000773 | F10: N-RPT/Event | H10: คุณสรัญญา วาณิชยโชค | I10: Origin Place Bangna | J10: 646 | K10: 69158.88 | L10: 74000 | P10: 69158.88 | Q10: 1 | S10: หญิง | T10: นุ๊ก | U10: ส่งมอบแล้ว
A11: 45931 | B11: 2025 | C11: 50 | E11: WAG-SONO25-000654 | F11: N-RPT/Event | H11: คุณจินห์จุฑา พงศ์เศรษฐไพศาล | I11: Origin Place Bangna | J11: 704 | K11: 54672.9 | L11: 58500 | P11: 54672.9 | Q11: 1 | S11: หญิง | T11: นุ๊ก | U11: ส่งมอบแล้ว
A12: 45931 | B12: 2025 | C12: 49 | E12: WAG-SONO25-000649 | F12: N-RPT/Event | H12: คุณคณินทร์ สิทธิการ | I12: Origin Place Bangna | J12: 808 | K12: 20560.75 | L12: 22000 | P12: 20560.75 | Q12: 1 | S12: หญิง | T12: นุ๊ก | U12: ส่งมอบแล้ว
A13: 45931 | B13: 2025 | C13: 35 | E13: WAG-SONO25-000647 | F13: N-RPT/Event | G13: 45948 | H13: คุณธนวัฒน์ วาณิชย์สิริกุล | I13: Origin Place Bangna | J13: 832 | K13: 104897.2 | L13: 112240 | P13: 104897.2 | Q13: 1 | S13: หญิง | T13: นุ๊ก | U13: ส่งมอบแล้ว
A14: 45992 | B14: 2025 | C14: 51 | E14: WAG-SONO25-000926 | F14: N-RPT/Event | H14: คุณพิมพ์ลดา มีเฟีย | I14: Origin Place Bangna | J14: 940 | K14: 59532.71 | L14: 63700 | P14: 59532.71 | Q14: 1 | S14: หญิง | T14: นุ๊ก | U14: ส่งมอบแล้ว
A15: 46054 | B15: 2026 | C15: 38 | E15: WAG-SONO26-000144 | F15: N-RPT/Event | G15: 46074 | H15: คุณเหม่ จู เฉิน | I15: Origin Place Bangna | J15: 1138 | K15: 14018.69 | L15: 15000 | P15: 14018.69 | Q15: 1 | S15: หญิง | T15: นุ๊ก | U15: ส่งมอบแล้ว
A16: 45931 | B16: 2025 | C16: 10 | F16: N-RPT/Event | G16: 45949 | H16: คุณนภาพร แย้มวาที | I16: Origin Place Bangna | J16: 1204 | K16: 21500 | M16: 5000 | R16: จองสิทธิ์ | S16: จอส | U16: ดำเนินการ
A17: 45931 | B17: 2025 | C17: 10 | F17: N-RPT/Event | G17: 45949 | H17: คุณธิติวุฒิ หู | I17: Origin Place Bangna | J17: 1239 | K17: 450000 | M17: 230000 | R17: 0.5 | S17: หญิง | T17: นุ๊ก | U17: ดำเนินการ
A18: 45931 | B18: 2025 | C18: 10 | F18: N-RPT/Event | G18: 45949 | H18: คุณวีริสา กิจบุญชัย | I18: Origin Place Bangna | J18: 1241 | K18: 43000 | M18: 5000 | R18: จองสิทธิ์ | S18: หญิง | U18: ดำเนินการ
A19: 45931 | B19: 2025 | C19: 10 | F19: N-RPT/Event | G19: 45949 | H19: คุณวีริสา กิจบุญชัย | I19: Origin Place Bangna | J19: 1241 | K19: 106300 | M19: 5000 | R19: จองสิทธิ์ | S19: หญิง | U19: ดำเนินการ
A20: 45931 | B20: 2025 | C20: 10 | F20: N-RPT/Event | G20: 45949 | H20: คุณวีริสา กิจบุญชัย | I20: Origin Place Bangna | J20: 1241 | K20: 148600 | M20: 3000 | R20: จองสิทธิ์ | S20: หญิง | U20: ดำเนินการ
A21: 46054 | B21: 2026 | C21: 2 | F21: N-RPT/Event | G21: 46071 | H21: คุณณัฐญา วุ้นประสิทธิ์ศักดิ์ | I21: Origin Place Khonkaen | J21: B833 | K21: 36030 | M21: 8015 | R21: 0.5 | S21: จอส | T21: PM | U21: ดำเนินการ
A22: 46023 | B22: 2026 | C22: 1 | F22: N-RPT/Event | G22: 46047 | H22: คุณพิลาวรรณ สาราษฏร์ | I22: Origin Place Khonkaen | J22: B526 | K22: 108360 | M22: 5000 | R22: จองสิทธิ์ | S22: จอส | U22: ดำเนินการ
A23: 46054 | B23: 2026 | C23: 2 | F23: N-RPT/Event | G23: 46054 | H23: คุณพีรพล จ่าเคน | I23: Origin Place Khonkaen | J23: A414 | K23: 300000 | M23: 5000 | R23: จองสิทธิ์ | S23: จอส | U23: ดำเนินการ
A24: 46023 | B24: 2026 | C24: 1 | F24: N-RPT/Event | H24: คุณพิลาวรรณ สาราษฏร์ | I24: Origin Place Khonkaen | J24: B526 | K24: 108360 | M24: 5000 | R24: จองสิทธิ์ | S24: จอส | U24: ดำเนินการ
A25: 46054 | B25: 2026 | C25: 2 | F25: N-RPT/Event | G25: 46054 | H25: คุณพีรพล จ่าเคน | I25: Origin Place Khonkaen | J25: A414 | K25: 300000 | M25: 5000 | R25: จองสิทธิ์ | S25: จอส | U25: ดำเนินการ
A26: 46023 | B26: 2026 | C26: 1 | F26: N-RPT/Event | G26: 46047 | H26: พีรพัฒน์ พัฒนเจริญ | I26: Origin Place Khonkaen | J26: A716 | K26: 30000 | S26: อั๋น | U26: ดำเนินการ
A27: 46023 | B27: 2026 | C27: 1 | F27: N-RPT/Event | G27: 46047 | H27: ณัฐชา จิราวัฒนพงษ์ | I27: Origin Place Khonkaen | J27: A533 | K27: 200000 | S27: อั๋น | U27: ดำเนินการ
A28: 46023 | B28: 2026 | C28: 1 | F28: N-RPT/Event | G28: 46047 | H28: วราพร เทพบรรหาร | I28: Origin Place Khonkaen | J28: A802 | K28: 200000 | S28: อั๋น | U28: ดำเนินการ
A29: 46023 | B29: 2026 | C29: 1 | F29: N-RPT/Event | G29: 46047 | H29: พัชรี เผื่อนงูเหลือม | I29: Origin Place Khonkaen | J29: B527 | K29: 300000 | S29: อั๋น | U29: ดำเนินการ
A30: 46023 | B30: 2026 | C30: 1 | F30: N-RPT/Event | G30: 46047 | H30: ปิยธิดา เมาะราษี | I30: Origin Place Khonkaen | J30: A527 | K30: 27560 | S30: อั๋น | U30: ดำเนินการ
A31: 46023 | B31: 2026 | C31: 1 | F31: N-RPT/Event | G31: 46047 | H31: ศรีจันทร์ ฉินวรรณเลิศ | I31: Origin Place Khonkaen | J31: B531 | K31: 79000 | S31: อั๋น | U31: ดำเนินการ
A32: 46023 | B32: 2026 | C32: 1 | F32: N-RPT/Event | G32: 46047 | H32: ศรีจันทร์ ฉินวรรณเลิศ | I32: Origin Place Khonkaen | J32: B402 | K32: 66000 | S32: อั๋น | U32: ดำเนินการ
A33: 46023 | B33: 2026 | C33: 1 | F33: N-RPT/Event | G33: 46047 | H33: ณััฐพงษ์ รักแก้ว | I33: Origin Place Khonkaen | J33: B713 | K33: 30560 | S33: อั๋น | U33: ดำเนินการ
A34: 46023 | B34: 2026 | C34: 1 | F34: N-RPT/Event | G34: 46047 | H34: ณััฐพงษ์ รักแก้ว | I34: Origin Place Khonkaen | J34: B710 | K34: 31840 | S34: อั๋น | U34: ดำเนินการ
A35: 46023 | B35: 2026 | C35: 1 | F35: N-RPT/Event | G35: 46047 | H35: วราลักษณ์ พรพิพัฒนวงษ์ | I35: Origin Place Khonkaen | J35: A630 | K35: 150000 | S35: อั๋น | U35: ดำเนินการ
A36: 46054 | B36: 2026 | C36: 2 | F36: N-RPT/Event | G36: 46068 | H36: สุกัญญา เด่นกองพล | I36: Origin Place Khonkaen | J36: B201 | S36: อั๋น | U36: ดำเนินการ
A37: 46054 | B37: 2026 | C37: 2 | F37: N-RPT/Event | G37: 46068 | H37: ปวีณา ชัณณกุล | I37: Origin Place Khonkaen | J37: B211 | K37: 377000 | S37: อั๋น | U37: ดำเนินการ
A38: 45870 | B38: 2025 | C38: 8 | F38: N-RPT/Event | G38: 45880 | H38: คุณศิริพร จันทร์ปิง | I38: Origin Play Bangkhunnon | J38: 1012 | K38: 179000 | M38: 94500 | R38: 0.5 | S38: แป้ง | U38: ดำเนินการ
A39: 45870 | B39: 2025 | C39: 8 | F39: N-RPT/Event | G39: 45880 | H39: คุณธนวัฒน์ เคารพาพงศ์ | I39: Origin Play Bangkhunnon | J39: 1512 | K39: 13000 | M39: 11500 | R39: 0.5 | S39: แป้ง | U39: ดำเนินการ
A40: 45870 | B40: 2025 | C40: 8 | E40: WAG-SONO25-000830 | F40: N-RPT/Event | G40: 45880 | H40: คุณพิมพลอย แก่นแก้ว | I40: Origin Play Bangkhunnon | J40: 1908 | K40: 27690 | M40: 16345 | R40: 0.5 | S40: แฮ็ค | T40: แบงค์ | U40: ดำเนินการ
...

Sheet Event Report
A1: No | B1: Project | C1: Event | D1: Event name | E1: Event Date | F1: Year-Month | G1: ลูกค้าที่มา | H1: ลูกค้าแอดไลน์ | I1: จำนวนรับลูกค้า | J1: จำนวนที่ปิดได้ | K1: Conversion rate | L1: rev. | M1: จำนวนตามต่อ
B2: Origin Play Bangkhunnon | C2: Financial day | D2: FND #1 | E2: 45969 | F2: =year(E2)&"-"&MONTH(E2) -> 2025-11 | K2: =J2/I2 -> #DIV/0! | L2: 5406620 | M2: =H2-J2 -> 0 | N2: =IFERROR(__xludf.DUMMYFUNCTION("AI("""")"),"5,406,620.00") -> 5,406,620.00
B3: Origin Play Bangkhunnon | C3: Room Transfer | D3: Transfer #1 | E3: 45990 | F3: =year(E3)&"-"&MONTH(E3) -> 2025-11 | K3: =J3/I3 -> #DIV/0! | L3: 906925 | M3: =H3-J3 -> 0
B4: Origin Play Bangkhunnon | C4: Room Transfer | D4: Transfer #2 | E4: 45991 | F4: =year(E4)&"-"&MONTH(E4) -> 2025-11 | K4: =J4/I4 -> #DIV/0! | L4: 609500 | M4: =H4-J4 -> 0
B5: Origin Play Bangkhunnon | C5: Room Transfer | D5: Transfer #3 | E5: 45998 | F5: =year(E5)&"-"&MONTH(E5) -> 2025-12 | K5: =J5/I5 -> #DIV/0! | L5: 719540 | M5: =H5-J5 -> 0
B6: Origin Play Bangkhunnon | C6: Room Transfer | D6: Transfer #4 | E6: 46004 | F6: =year(E6)&"-"&MONTH(E6) -> 2025-12 | K6: =J6/I6 -> #DIV/0! | L6: 522000 | M6: =H6-J6 -> 0
B7: Origin Place Bangna | C7: Financial day | F7: =year(E7)&"-"&MONTH(E7) -> 1899-12 | K7: =J7/I7 -> #DIV/0! | M7: =H7-J7 -> 0
B8: Origin Place Bangna | C8: Room Transfer | D8: Transfer #1 | E8: 45949 | F8: =year(E8)&"-"&MONTH(E8) -> 2025-10 | K8: =J8/I8 -> #DIV/0! | L8: 1361000 | M8: =H8-J8 -> 0
B9: Origin Place Bangna | C9: Room Transfer | D9: Transfer #2 | E9: 45955 | F9: =year(E9)&"-"&MONTH(E9) -> 2025-10 | I9: 10 | J9: 5 | K9: =J9/I9 -> 0.5 | L9: 716760 | M9: =H9-J9 -> -5
B10: The Origin Bangkae | C10: Financial day | F10: =year(E10)&"-"&MONTH(E10) -> 1899-12 | K10: =J10/I10 -> #DIV/0! | M10: =H10-J10 -> 0
B11: The Origin Bangkae | C11: Room Transfer | D11: Transfer #1 | E11: 45962 | F11: =year(E11)&"-"&MONTH(E11) -> 2025-11 | G11: 95 | H11: 49 | J11: 7 | K11: =J11/I11 -> #DIV/0! | L11: 638040 | M11: =H11-J11 -> 42
B12: The Origin Bangkae | C12: Room Transfer | D12: Transfer #2 | E12: 46011 | F12: =year(E12)&"-"&MONTH(E12) -> 2025-12 | H12: 35 | I12: 35 | J12: 4 | K12: =J12/I12 -> 0.11428571 | L12: 343500 | M12: =H12-J12 -> 31
B13: The Origin Praksa | D13: Transfer #1 | F13: =year(E13)&"-"&MONTH(E13) -> 1899-12 | K13: =J13/I13 -> #DIV/0! | M13: =H13-J13 -> 0
B14: The Origin Praksa | C14: Room Transfer | D14: Transfer #2 | E14: 45949 | F14: =year(E14)&"-"&MONTH(E14) -> 2025-10 | K14: =J14/I14 -> #DIV/0! | L14: 1032600 | M14: =H14-J14 -> 0
B15: The Origin Praksa | C15: Room Transfer | D15: Transfer #3 | E15: 45962 | F15: =year(E15)&"-"&MONTH(E15) -> 2025-11 | G15: 33 | H15: 8 | J15: 5 | K15: =J15/I15 -> #DIV/0! | L15: 305110 | M15: =H15-J15 -> 3
B16: The Origin Praksa | C16: Room Transfer | D16: Transfer #4 | E16: 45969 | F16: =year(E16)&"-"&MONTH(E16) -> 2025-11 | K16: =J16/I16 -> #DIV/0! | L16: 98000 | M16: =H16-J16 -> 0
B17: The Origin Phahol 57 | C17: Financial day | F17: =year(E17)&"-"&MONTH(E17) -> 1899-12 | K17: =J17/I17 -> #DIV/0! | M17: =H17-J17 -> 0
B18: The Origin Phahol 57 | C18: Room Transfer | D18: Transfer #1 | E18: 45969 | F18: =year(E18)&"-"&MONTH(E18) -> 2025-11 | K18: =J18/I18 -> #DIV/0! | L18: 612050 | M18: =H18-J18 -> 0
B19: The Origin Phahol 57 | C19: Room Transfer | D19: Transfer #2 | E19: 45970 | F19: =year(E19)&"-"&MONTH(E19) -> 2025-11 | K19: =J19/I19 -> #DIV/0! | L19: 1331760 | M19: =H19-J19 -> 0
B20: The Origin Phahol 57 | C20: Room Transfer | D20: Transfer #3 | E20: 45984 | F20: =year(E20)&"-"&MONTH(E20) -> 2025-11 | K20: =J20/I20 -> #DIV/0! | L20: 202800 | M20: =H20-J20 -> 0
B21: Origin Play Bangsaen | C21: Financial day | D21: FND #1 | E21: 45955 | F21: =year(E21)&"-"&MONTH(E21) -> 2025-10 | I21: 5 | J21: 4 | K21: =J21/I21 -> 0.8 | M21: =H21-J21 -> -4
B22: Origin Play Bangsaen | C22: Room Transfer | D22: Transfer #1 | E22: 45983 | F22: =year(E22)&"-"&MONTH(E22) -> 2025-11 | G22: 51 | J22: 14 | K22: =J22/I22 -> #DIV/0! | L22: 2270600 | M22: =H22-J22 -> -14
B23: Origin Play Bangsaen | C23: Room Transfer | D23: Transfer #2 | E23: 45991 | F23: =year(E23)&"-"&MONTH(E23) -> 2025-11 | G23: 14 | H23: 11 | I23: 11 | J23: 5 | K23: =J23/I23 -> 0.45454545 | L23: 652610 | M23: =H23-J23 -> 6
B24: Origin Play Bangsaen | C24: Room Transfer | D24: Transfer #3 | E24: 45997 | F24: =year(E24)&"-"&MONTH(E24) -> 2025-12 | H24: 21 | I24: 21 | J24: 6 | K24: =J24/I24 -> 0.28571429 | L24: 868470 | M24: =H24-J24 -> 15
B25: Origin Play Bangsaen | C25: Room Transfer | D25: Transfer #4 | E25: 46004 | F25: =year(E25)&"-"&MONTH(E25) -> 2025-12 | H25: 17 | I25: 17 | J25: 2 | K25: =J25/I25 -> 0.11764706 | L25: 221340 | M25: =H25-J25 -> 15
C26: Room Transfer | D26: Transfer #5 | E26: 46011 | F26: =year(E26)&"-"&MONTH(E26) -> 2025-12 | G26: 21 | H26: 9 | I26: 9 | J26: 1 | K26: =J26/I26 -> 0.11111111 | L26: 95710 | M26: =H26-J26 -> 8
B27: The Origin Kathu-Patong | C27: Financial day | D27: FND #1 | E27: 45949 | F27: =year(E27)&"-"&MONTH(E27) -> 2025-10 | K27: =J27/I27 -> #DIV/0! | L27: 3404520 | M27: =H27-J27 -> 0
B28: The Origin Kathu-Patong | C28: Financial day | D28: FND #2 | E28: 45970 | F28: =year(E28)&"-"&MONTH(E28) -> 2025-11 | K28: =J28/I28 -> #DIV/0! | L28: 970000 | M28: =H28-J28 -> 0
B29: The Origin Kathu-Patong | C29: Wyde | D29: Wyde Creative Talk | E29: 46011 | F29: =year(E29)&"-"&MONTH(E29) -> 2025-12 | K29: =J29/I29 -> #DIV/0! | L29: 639310 | M29: =H29-J29 -> 0
B30: The Origin Kathu-Patong | C30: Room Transfer | D30: Transfer #1 | E30: 46061 | F30: =year(E30)&"-"&MONTH(E30) -> 2026-2 | K30: =J30/I30 -> #DIV/0! | L30: 2600000 | M30: =H30-J30 -> 0
B31: Origin Place Khonkaen | C31: Financial day | D31: FND #1 | E31: 46047 | F31: =year(E31)&"-"&MONTH(E31) -> 2026-1 | J31: 14 | K31: =J31/I31 -> #DIV/0! | L31: 1364480 | M31: =H31-J31 -> -14
B32: Origin Place Khonkaen | C32: Room Transfer | D32: Transfer #1 | E32: 46067 | F32: =year(E32)&"-"&MONTH(E32) -> 2026-2 | G32: 39 | H32: 21 | J32: 8 | K32: =J32/I32 -> #DIV/0! | L32: 909375 | M32: =H32-J32 -> 13
B33: Origin Place Khonkaen | C33: Room Transfer | D33: Transfer #4 | E33: 46102 | F33: =year(E33)&"-"&MONTH(E33) -> 2026-3 | J33: 9 | K33: =J33/I33 -> #DIV/0! | L33: 693187 | M33: =H33-J33 -> -9
B34: SO Origin Siriraj | C34: Financial day | D34: FND #1 | E34: 46096 | F34: =year(E34)&"-"&MONTH(E34) -> 2026-3 | K34: =J34/I34 -> #DIV/0! | L34: 6141280 | M34: =H34-J34 -> 0
B35: SO Origin Siriraj | C35: Condo Sale | D35: มหกรรมบ้านและคอนโด | F35: =year(E35)&"-"&MONTH(E35) -> 1899-12 | K35: =J35/I35 -> #DIV/0! | M35: =H35-J35 -> 0
A36: 1 | B36: Origin Thonglor world - IP | C36: Financial day | E36: 46120 | F36: 46113 | G36: 50 | H36: 25 | I36: 10 | J36: 10 | K36: =IFERROR(J36/I36, 0) -> 1 | L36: 1000000 | M36: 0

Sheet Monthly 
A1: Department | B1: > | C1: WYDE SALES
A2: Choose month | B2: > | C2: MAR 26 | D2: 😀 | E2: 😀 | F2: 😀 | G2: 😀 | H2: 😀 | I2: 😀 | J2: 😀 | N2: > | P2: > | T2: >
C3: =VLOOKUP(C2,'Back up sheet'!$C$15:$D$26,2,0) -> #REF!
C4: MONTHLY PERFORMANCE | D4: YING | E4: PANG | F4: JOSH | G4: HACK | H4: MINT(EDH) | I4: PHON | J4: AUN | K4: B2B | M4: TOTAL | Q4: TEAM JEAB | R4: TEAM AOM | S4: TEAM B2B
C5: เป้าขาย | D5: 3000000 | E5: 3000000 | F5: 3000000 | G5: 2000000 | H5: 0 | I5: 3000000 | J5: 3000000 | K5: 0 | M5: =Sum(D5:K5) -> 17000000 | Q5: =sum(D5:H5) -> 11000000 | R5: =sum(I5:J5) -> 6000000 | S5: =K5 -> 0
C6: ยอด | D6: =SUM(D7) -> #N/A | E6: =SUM(E7) -> #N/A | F6: =SUM(F7) -> #N/A | G6: =SUM(G7) -> #N/A | H6: =SUM(H7) -> #N/A | I6: =SUM(I7) -> #N/A | J6: =SUM(J7) -> #N/A | K6: =SUM(K7) -> #N/A | M6: =SUM(M7) -> #N/A | Q6: =SUM(Q7) -> #N/A | R6: =SUM(R7) -> #N/A | S6: =SUM(S7) -> #N/A
C7: ยอดขาย "2026 ขายใหม่" | D7: =SUMIFS('Sales Ying'!$P:$P,'Sales Ying'!$A:$A,"2026ขายใหม่",'Sales Ying'!$N:$N,C3) -> #N/A | E7: =SUMIFS('Sales Pang'!$P:$P,'Sales Pang'!$A:$A,"2026ขายใหม่",'Sales Pang'!$N:$N,C3) -> #N/A | F7: =SUMIFS('Sales Josh'!$P:$P,'Sales Josh'!$A:$A,"2026ขายใหม่",'Sales Josh'!$N:$N,C3) -> #N/A | G7: =SUMIFS('Sales Hack'!$P:$P,'Sales Hack'!$A:$A,"2026ขายใหม่",'Sales Hack'!$N:$N,C3) -> #N/A | H7: =SUMIFS('Sales Mint'!$P:$P,'Sales Mint'!$A:$A,"2026ขายใหม่",'Sales Mint'!$N:$N,C3) -> #N/A | I7: =SUMIFS('Sales Phon'!$P:$P,'Sales Phon'!$A:$A,"2026ขายใหม่",'Sales Phon'!$N:$N,C3) -> #N/A | J7: =SUMIFS('Sales Aun'!$P:$P,'Sales Aun'!$A:$A,"2026ขายใหม่",'Sales Aun'!$N:$N,C3) -> #N/A | K7: =SUMIFS('Sales B2B'!$P:$P,'Sales B2B'!$A:$A,"2026ขายใหม่",'Sales B2B'!$N:$N,C3) -> #N/A | M7: =Sum(D7:K7) -> #N/A | Q7: =sum(D7:H7) -> #N/A | R7: =sum(I7:J7) -> #N/A | S7: =K7 -> #N/A
C9: Tracking By Lead From
C10: Facebook
C11: Instagram
C12: LINE OA
C13: OPA
C14: หาเอง
C15: Tracking By Contact
C18: Tracking By Status
C19: จอง
C20: ลงทะเบียน
C21: ส่งใบเสนอราคา
C22: ฺBacklog
... C27: งานอื่นๆ
A29: >

Sheet ชีต30

Sheet ชีต31

Sheet DashBoard

Sheet Team PAom
A1: No. | B1: Assign date | C1: Sales Activity | D1: Project /Client | E1: Sales | F1: Deadline | G1: มูลค่าคาดากาณ์ | H1: สถานะ | I1: Design Package | J1: Remark | K1: Next Action
A2: 1 | B2: 25281 | C2: หาเอง | D2: Customers | E2: kathu-patong | F2: คุณกุลชญา คีรีรักษ์ | G2: C828 | I2: Premium(L)
A3: 2 | B3: 25281 | C3: หาเอง | D3: Customers | E3: kathu-patong | F3: คุณกุลชญา คีรีรักษ์ | G3: C428 | I3: Premium(L)
A4: 3 | B4: 25281 | C4: LINE OA | D4: Customers | E4: kathu-patong | F4: Mr.Thi Thanh Tam HOANG | G4: C605 | I4: Medium(M)
A5: 4 | B5: 25281 | C5: LINE OA | D5: Customers | E5: kathu-patong | F5: Oleg Foltyn | G5: B405 | I5: Combo(S)
A6: 5 | B6: 25281 | C6: LINE OA | D6: Customers | E6: kathu-patong | F6: สุวคนธ์ พิทยานันทกิจ | I6: Combo(S)
A7: 6 | B7: 25281 | C7: LINE OA | D7: Customers | E7: kathu-patong | F7: นงลักษณ์ ตั้งขันติกุล | G7: C422 | I7: Premium(L)
A8: 7 | B8: 25281 | C8: LINE OA | D8: Customers | E8: kathu-patong | F8: ชณิตา ปาริเวสัง | G8: B305 | I8: Medium(M)
A9: 8 | B9: 25281 | C9: LINE OA | D9: Customers | E9: kathu-patong | F9: สุวคนธ์ พิทยานันทกิจ | G9: B310 | I9: Medium(M)
A10: 9 | B10: 25281 | C10: LINE OA | E10: kathu-patong | F10: ฐิติวัลคุ์ ลักษณะวิมล | G10: B432 | I10: Premium(L)
A11: 10 | B11: 25281 | C11: LINE OA | E11: kathu-patong | F11: Slimane, Moustapha DAGHMANI | G11: C631 | I11: Medium(M)
A12: 11 | B12: 25281 | E12: kathu-patong | F12: Anthony Fred William BOULANGER | G12: C817 | I12: Premium(L)
A13: 12 | B13: 25281 | E13: tonglor world | F13: pattie | I13: Premium(L)
A14: 13 | B14: 25281 | E14: kathu-patong | F14: บอร์ดแคช ไลน์ออฟฟิเซียล | H14: บอร์ดแคช ไลน์ออฟฟิเซียล
A15: 14 | B15: 25281 | E15: kathu-patong | F15: โทรตามลูกค้าร่วมกิจกรรม GTK | H15: โทรตามลูกค้าร่วมกิจกรรม GTK
A16: 15 | B16: 25282 | E16: kathu-patong | F16: จัดบูธ กระทู้-ภูเก็ต | H16: จัดบูธ กระทู้-ภูเก็ต
A17: 16 | B17: 25282 | E17: kathu-patong | F17: ดูหน้างานบางเทา-ภูเก็ต | H17: ดูหน้างานบางเทา-ภูเก็ต
A18: 17 | B18: 25282 | E18: kathu-patong | F18: พัชร์กันต์ อนันต์นฤนาถ | G18: A419 | I18: Premium(L)
A19: 18 | B19: 25282 | E19: kathu-patong | F19: กุลธิดา ดินแดง | G19: B512 | I19: Medium(M)
A20: 19 | B20: 25282 | E20: kathu-patong | F20: ชาลิสา มัลลัม | G20: C531 | I20: Medium(M)
A21: 20 | B21: 25282 | E21: kathu-patong | F21: อรวรรณ ใจกล้า | G21: B416 | I21: Medium(M)
A22: 21 | B22: 25282 | E22: kathu-patong | F22: ดาริสา กรดสุริกาญจน์ | G22: A325 | I22: Medium(M)
A23: 22 | B23: 25282 | E23: kathu-patong | F23: ศิริลักษณ์ แก้วมณี | G23: C308 | I23: Combo(S)
A24: 23 | B24: 25283 | E24: kathu-patong | F24: Mr.Ghanim Sirelkhatim Ataia | G24: B703 | I24: Premium(L)
A25: 24 | B25: 25283 | E25: kathu-patong | F25: Mr.Ghanim Sirelkhatim Ataia | G25: B704 | I25: Premium(L)
A26: 25 | B26: 25283 | E26: kathu-patong | F26: Mr.Ghanim Sirelkhatim Ataia | G26: B705 | I26: Premium(L)
A27: 26 | B27: 25283 | E27: kathu-patong | F27: Mr.Ghanim Sirelkhatim Ataia | G27: B706 | I27: Premium(L)
A28: 27 | B28: 25283 | E28: kathu-patong | F28: Mr.Ghanim Sirelkhatim Ataia | G28: B707 | I28: Premium(L)
A29: 28 | B29: 25283 | E29: kathu-patong | F29: นส.ลลิตภัทร สุวรรณทิพย์ | G29: A723 | I29: Combo(S)
... A38: 37 | B38: 25284 | E38: kathu-patong | F38: คุณอาไรด้า ชินพงศ์ | G38: C208 | I38: Combo(S)
A39: 38 | B39: 25285 | E39: kathu-patong | F39: สไลด์weekly Update Phuket-Wyde interior | H39: สไลด์weekly Update Phuket-Wyde interior
A40: 39 | B40: 25285 | E40: kathu-patong | F40: โพสต์รายได้+ตามเอกสาร | H40: โพสต์รายได้+ตามเอกสาร
A41: 40 | B41: 25285 | E41: kathu-patong | F41: Slimane, Moustapha DAGHMANI | G41: C631 | H41: Slimane, Moustapha DAGHMANI | I41: Medium(M)
A42: 41 | B42: 25285 | E42: kathu-patong | F42: Mr.Anh Pha Le | G42: C611 | I42: Medium(M)
A43: 42 | B43: 25285 | E43: kathu-patong | F43: คุณชาลิสา มัลลัม | G43: C531 | I43: Combo(S)
A44: 43 | B44: 25285 | E44: kathu-patong | F44: ธนเทพ อนันพิพัฒพงศ์ | G44: B431 | I44: Combo(S)
A45: 44 | B45: 25285 | E45: kathu-patong | F45: คุณชณิตา ปาริเวสัง | G45: B305 | I45: Medium(M)
B46: 25285 | E46: kathu-patong
A47: 45 | B47: 25285 | E47: kathu-patong | F47: โพสต์รายได้+ตามเอกสาร
A48: 46 | B48: 25285 | E48: kathu-patong | F48: เปิด PO-PR lotแรก บ้างส่วน
...

Sheet Aun
B2: TEAM P' AOM | C2: ( B2B & B2C)
B5: Daily sales report
B6: Sales : Supakron Potisorn (Aun)
A9: No. | B9: Contact date | C9: Project | D9: Room | E9: Name (Customer) | F9: รายละเอียดการทำงาน | G9: Design Package | H9: คาดยอดขาย | I9: โอกาสปิด (%) | J9: Next Update /Action Plan | K9: Remark
A10: 1 | B10: 25332 | C10: Origin Place Petkasem | D10: 2006 | E10: ไพจิตร ดิสสานนท์ | F10: ✅ จอง | H10: 200000 | I10: มัดจำสิทธิ์ | J10: ส่งบรีฟ designer ทำแบบ | K10: รอคุยรายละเอียด Event Transfer
A11: 2 | B11: 25332 | C11: Origin Place Petkasem | D11: 805 | E11: ศราพร ศราภัยวานิช | F11: ✅ จอง | H11: 39000 | I11: มัดจำสิทธิ์ | J11: ส่งบรีฟ designer ทำแบบ | K11: รอคุยรายละเอียด Event Transfer
A12: 3 | B12: 25332 | C12: Origin Place Petkasem | D12: 508 | E12: จิตราภรณ์ ควรประดิษฐ์ | F12: ✅ จอง | H12: 55000 | I12: มัดจำสิทธิ์ | J12: ส่งบรีฟ designer ทำแบบ | K12: รอคุยรายละเอียด Event Transfer
A13: 4 | B13: 25332 | C13: Origin Place Petkasem | D13: 1003 | E13: อนิวัช ทั้งวงศ์สกุล | F13: ✅ จอง | H13: 300000 | I13: มัดจำสิทธิ์ | J13: ส่งบรีฟ designer ทำแบบ | K13: รอคุยรายละเอียด Event Transfer
A14: 5 | B14: 25332 | C14: Origin Place Petkasem | D14: 1220 | E14: กิตตินันท์ สุขนันที | F14: ✅ จอง | H14: 200000 | I14: มัดจำสิทธิ์ | J14: ส่งบรีฟ designer ทำแบบ | K14: รอคุยรายละเอียด Event Transfer
A15: 6 | B15: 25332 | C15: Origin Place Petkasem | D15: 506 | E15: นารดา แซ่จัง | F15: ยกเลิก | H15: 150000 | I15: มัดจำสิทธิ์ | J15: ส่งบรีฟ designer ทำแบบ | K15: รอคุยรายละเอียด Event Transfer
A16: 7 | B16: 25332 | C16: Origin Place Petkasem | D16: 1615 | E16: อารีย์ เจริญมี | F16: ✅ จอง | H16: 300000 | I16: มัดจำสิทธิ์ | J16: ส่งบรีฟ designer ทำแบบ | K16: รอคุยรายละเอียด Event Transfer
A17: 8 | B17: 25336 | C17: The Klever Residence | E17: บริษัท เอส พาร์ค ทรี จำกัด | F17: ✅ จอง | H17: 220616.88 | I17: มัดจำสิทธิ์ | J17: ส่งบรีฟ designer ทำแบบ | K17: ทำเอกสารส่งมอบ วางบิล
A18: 9 | B18: 25335 | C18: R&B KARAOKE DONGKI THONGLOR | E18: คุณพงษ์ CM | F18: 🔄ส่งใบเสนอราคา | H18: 17401006 | I18: 0.5 | J18: ติดตามใบเสนอราคา 3 Day 15/05/2026
A19: 10 | B19: 25336 | C19: Add work power outlet / Park Burlington type B | E19: คุุณอ้อ Siam masterpice asset | F19: 🔄ส่งใบเสนอราคา | H19: 21186 | I19: 0.9 | J19: ติดตามใบเสนอราคา 3 Day 15/05/2027
A20: 11 | B20: 25336 | C20: Add work power outlet / Park Burlington type D | E20: คุุณอ้อ Siam masterpice asset | F20: 🔄ส่งใบเสนอราคา | H20: 50494 | I20: มัดจำสิทธิ์ | J20: ติดตามใบเสนอราคา 3 Day 15/05/2028
A21: 12 | B21: 25342 | C21: ฺDesign Baan Khun Pang-Luddawan House | E21: K .pang | F21: ติดตามครั้งที่ 2 | H21: 279299 | I21: 0.2 | J21: ติดตามใบเสนอราคา 14 Day 05/06/2028 | K21: ยังไม่ตัดสินใจ/ยังไม่ตัดสินใจ
A22: 13 | B22: 25352 | C22: Build -in GBB-BN plot 16 S type S | E22: บริษัท เอสซแอสเสท คอร์ปอเรช่ัน จำกัด (มหาชน) | F22: ลูกค้าได้ผู้เราหมาแล้ว Close lead | H22: 8778141.1 | I22: 0.5 | J22: E-Bidding 10/06/2026
A23: 14 | B23: 25352 | C23: Build -in GBB-BN plot 16 S type M | E23: บริษัท เอสซแอสเสท คอร์ปอเรช่ัน จำกัด (มหาชน) | F23: ลูกค้าได้ผู้เราหมาแล้ว Close lead | H23: 10077009 | I23: 0.5 | J23: E-Bidding 10/06/2027
A24: 15 | B24: 25352 | C24: Build -in GBB-BN plot 16 S type L | E24: บริษัท เอสซแอสเสท คอร์ปอเรช่ัน จำกัด (มหาชน) | F24: ลูกค้าได้ผู้เราหมาแล้ว Close lead | H24: 16209502 | I24: 0.5 | J24: E-Bidding 10/06/2028
A25: 16 | B25: 25353 | C25: Build -in GBB-PKN plot 16 S type S | E25: บริษัท เอสซแอสเสท คอร์ปอเรช่ัน จำกัด (มหาชน) | F25: ลูกค้าได้ผู้เราหมาแล้ว Close lead | H25: 8778141.1 | I25: 0.5 | J25: E-Bidding 10/06/2029
A26: 17 | B26: 25353 | C26: Build -in GBB-PKN plot 16 S type M | E26: บริษัท เอสซแอสเสท คอร์ปอเรช่ัน จำกัด (มหาชน) | F26: ลูกค้าได้ผู้เราหมาแล้ว Close lead | H26: 10077009 | I26: 0.5 | J26: E-Bidding 10/06/2030
A27: 18 | B27: 25358 | C27: Sky ville Hotel Sukumvit 24 Lounge 37 Floor | E27: K . somsak CM | F27: 🔄ส่งใบเสนอราคา | H27: 5675954.7 | I27: 0.5 | J27: พิจารณาราคา ร่วมกับ 35-36 floor 11/06/2026
A28: 19 | B28: 25358 | C28: Sky ville Hotel Sukumvit 24 Lounge 36 Floor | E28: K . somsak CM | F28: 🔄ส่งใบเสนอราคา | I28: 0.5 | J28: รอใบเสนอราคา ส่ง 11/06/2026 | K28: ส่งใบเสนอราคา
A29: 20 | B29: 25358 | C29: Sky ville Hotel Sukumvit 24 Lounge 35 Floor | E29: K . somsak CM | F29: 🔄ส่งใบเสนอราคา | I29: 0.5 | J29: รอใบเสนอราคา ส่ง 11/06/2027
A30: 21 | B30: 25359 | C30: งาน wallpaper Bedroom 2-3 BAM HOUSE | E30: BAM DAIMOND | F30: 📝 ลงทะเบียน | I30: 0.5 | J30: รอเลื่อก spec และใบเสนอราคา
A31: 22 | B31: 25359 | C31: งานต่อเติมห้องนอน 6 BAM HOUSE | E31: BAM DAIMOND | F31: 📝 ลงทะเบียน | H31: 300000 | I31: 0.5 | J31: รอเลื่อก spec และใบเสนอราคา
A32: 23 | B32: 25360 | C32: Design office k.pae chonburi 80 sq.m | E32: k.pae | F32: 📝 ลงทะเบียน | H32: 200000 | I32: 0.2 | J32: ออกใบเสนอราคา
A33: 24 | B33: 25361 | C33: Renovate painhouse Pattaya | E33: Major Development public company | F33: ยกเลิก | H33: 800000 | I33: 0.2 | J33: ออกใบเสนอราคา
A34: 25 | B34: 25369 | C34: Renovate Mock up room CRAFT CONDO | E34: บริษัท สยามราชดำริ จำกัด | F34: 🔄ส่งใบเสนอราคา | H34: 212421.22 | I34: 0.5 | J34: ติดตามใบเสนอราคา 16/06/2026
A35: 26 | B35: 25371 | C35: Build-in showhouse grand burlington rama 3 type twin | E35: คุุณอ้อ Siam masterpice asset | F35: 📝 ลงทะเบียน | I35: 0.5 | J35: ออกใบเสนอราคา
A36: 27 | B36: 25371 | C36: Build-in showhouse grand burlington rama 3 town Home | E36: คุุณอ้อ Siam masterpice asset | F36: 📝 ลงทะเบียน | I36: 0.5 | J36: ออกใบเสนอราคา
A37: 28
A38: 29
A39: 30
A40: 31
A41: 32
A42: 33
A43: 34
A44: 35
A45: 36
...

Sheet Pon
B2: TEAM P' AOM | C2: ( B2B & B2C)
B5: Daily sales report
B6: Sales : Pornsiri Tistongkum (PON)
A9: No. | B9: Contact date | C9: Project | D9: Room | E9: Name (Customer) | F9: รายละเอียดการทำงาน | G9: Design Package | H9: คาดยอดขาย | I9: โอกาสปิด (%) | J9: Next Update /Action Plan | K9: Remark
A10: 1 | B10: 25334 | C10: The Origin Kathu-Pathong | D10: B507 | E10: Alexander Teplyakov | F10: ✅ จอง | H10: 21500 | I10: มัดจำสิทธิ์ | J10: จ่ายแล้ว
A11: 2 | B11: 25335 | C11: The Origin Kathu-Pathong | D11: C602 | E11: K.Bo Peng | F11: 🔄ส่งใบเสนอราคา | H11: 19500 | I11: 0.9 | J11: ส่งใบราคาใหม่อีกครั้ง
A12: 3 | B12: 25335 | C12: The Origin Kathu-Pathong | D12: C802 | E12: K.Bo Peng | F12: 🔄ส่งใบเสนอราคา | H12: 19500 | I12: 0.9 | J12: ส่งใบราคาใหม่อีกครั้ง
A13: 4 | B13: 25336 | C13: เบลกราเวีย-บางนาพระราม9 | D13: 98/33 | E13: K.เพ็ญ | F13: ✅ จอง | H13: 330000 | I13: 0.5 | J13: ผ่านพี่หมู-พี่เอ กฤษ
A14: 5 | B14: 25336 | C14: The Origin Kathu-Pathong | D14: C330 | E14: K.จริยวัฒน์ ศรียาภัย | F14: ต้องติดตามต่อ | H14: 16900 | I14: 0.2 | J14: 085-4854016
A15: 6 | B15: 25336 | C15: The Origin Kathu-Pathong | D15: C331 | E15: K.จริยวัฒน์ ศรียาภัย | F15: ต้องติดตามต่อ | H15: 16900 | I15: 0.2 | J15: 085-4854016
A16: 7 | B16: 25337 | C16: The Origin Kathu-Pathong | D16: B230 | E16: มณีรัตน์ บุญลาภ | F16: ต้องติดตามต่อ | H16: 50000 | I16: 0.5 | J16: 095-2648935
A17: 8 | B17: 25337 | C17: The Origin Kathu-Pathong | D17: A603 | E17: Mr.Andrea Donalisio | F17: ✅ จอง | H17: 152513 | I17: 0.9
A18: 9 | B18: 25338 | C18: The Origin Kathu-Pathong | D18: A717 | E18: คุณโชติกา รัตนวิริยะพิทักษ | F18: 🔄ส่งใบเสนอราคา | H18: 360000 | I18: 0.5
A19: 10 | B19: 25341 | C19: The Origin Kathu-Pathong | D19: A812 | E19: Mr.Andrea Donalisio | F19: ✅ จอง | H19: 69950 | I19: 0.9
A20: 11 | B20: 25341 | C20: The Origin Kathu-Pathong | D20: A816 | E20: AHTON CHUBCHENKO | F20: ✅ จอง | H20: 69000 | I20: 0.9
A21: 12 | B21: 25342 | C21: The Origin Kathu-Pathong | D21: B310 | E21: คุณชัญญา พิทยานันทกิจ | F21: ✅ จอง | H21: 34080 | I21: 0.9
A22: 13 | B22: 25343 | C22: The Origin Kathu-Pathong | D22: B401 | E22: คุณภณัชกรณ์ สหสันติวรกุล | F22: ✅ จอง | H22: 200000 | I22: 0.9
A23: 14 | B23: 25344 | C23: The Origin Kathu-Pathong | D23: B502 | E23: คุณนัทธพงศ์ แก้วหัวเมือง | F23: ✅ จอง | H23: 21500 | I23: 0.9
A24: 15 | B24: 25345 | C24: The Origin Kathu-Pathong | D24: B507 | E24: Alexander Teplyakov | F24: 🔄ส่งใบเสนอราคา | H24: 21500 | I24: 0.5
A25: 16 | B25: 25346 | C25: The Origin Kathu-Pathong | D25: B711 | E25: อัจฉรา พิเศษเมธา | F25: 🔄ส่งใบเสนอราคา | H25: 160000 | I25: 0.5
A26: 17 | B26: 25351 | C26: The Origin Kathu-Pathong | D26: B806 | E26: คุณโมชิน ราซา | F26: ✅ จอง | H26: 20800 | I26: 0.9
A27: 18 | B27: 25351 | C27: The Origin Kathu-Pathong | D27: C130 | E27: Pramjit Margaret Kaur | F27: ✅ จอง | H27: 31500 | I27: 0.9
A28: 19 | B28: 25351 | C28: The Origin Kathu-Pathong | D28: C131 | E28: Mrs .Johaneke Nicole Van | F28: ✅ จอง | H28: 470000 | I28: 0.5
... A38: 29 | B38: 25355 | C38: The Origin Kathu-Pathong | D38: C730 | E38: Fiona Anne Yung | F38: 🔄ส่งใบเสนอราคา | H38: 42900 | I38: 0.5
A39: 30 | B39: 25358 | C39: The Origin Kathu-Pathong | D39: - | E39: เลือกพรอพ คุณพัชรา | F39: งานอื่นๆ
A40: 31 | B40: 25358 | C40: The Origin Kathu-Pathong | D40: - | E40: เปิดอนุมัติ po-pr lot3 รอบแรก | F40: งานอื่นๆ
A41: 32 | B41: 25358 | C41: So origin Bangtao Beach | D41: B703 | E41: ประชุม บางเทา อัพเดทห้องลูกค้า Mr.Myron Ivan Haluk | F41: ✅ จอง | H41: 1500000 | I41: 0.5
A42: 33 | B42: 25358 | C42: The Origin Kathu-Pathong | D42: - | E42: เสนอราคา voucher lot4 /origin 6ห้อง | F42: งานอื่นๆ | H42: 150000 | I42: 0.9
A43: 34 | B43: 25358 | C43: The Origin Kathu-Pathong | D43: B422 | E43: คุณจันจิรา มณะโสต์ | F43: งานอื่นๆ | H43: 150000 | I43: 0.9
A44: 35 | B44: 25359 | C44: The Origin Kathu-Pathong | D44: C630 | E44: คุณจารุวรรณ พุทธเมฆ | F44: 🔄ส่งใบเสนอราคา | H44: 58200 | I44: 0.5
A45: 36 | B45: 25359 | C45: The Origin Kathu-Pathong | D45: C131 | E45: บรีบแบบสรุปให้เพื่อแก้ไขทำราคาอีกครั้ง | F45: งานอื่นๆ
A46: 37 | B46: 25359 | C46: The Origin Kathu-Pathong | D46: B512 | E46: คุณกุลธิดา ดินแดง | F46: ✅ จอง | H46: 83202 | I46: 0.9
A47: 38 | B47: 25359 | C47: The Origin Kathu-Pathong | D47: B331 | E47: คุณชัยรัตน์ ไฝสุข | F47: ✅ จอง | H47: 224000 | I47: 0.9
A48: 39 | B48: 25359 | C48: The Origin Kathu-Pathong | D48: B622 | E48: กนกณัฏ ทองช่วย | F48: ต้องติดตามต่อ
A49: 40 | B49: 25359 | C49: The Origin Kathu-Pathong | D49: - | E49: เปิดอนุมัติ po-pr lot3 เพิ่มเติม | F49: งานอื่นๆ
A50: 41 | B50: 25359 | C50: The Origin Kathu-Pathong | D50: - | E50: ตามลูกค้าเซ็นส่งมอบ lotแรก (คนไทย) | F50: งานอื่นๆ
A51: 42
A52: 43
A53: 44
A54: 45
...

Sheet Team PJeab
A1: No. | B1: Contact date | C1: Close date | D1: Where | E1: 0 | F1: Project | G1: Name (Customer) | H1: Room no. | I1: Phone | J1: Product Type | K1: Design Package | L1: คาดยอดขาย | M1: โอกาสปิด (%) | N1: SALES | O1: Status | P1: Next Update /Action Plan | Q1: Remark
F2: Origin Place Khonkaen | G2: โศจิรัตน์ เลิศวรวงศ์ | H2: B203 | I2: 0632696253
F3: Origin Place Khonkaen | G3: ฐิติมาศ ทับสกุล | H3: B206 | I3: 0849926654
F4: Origin Place Khonkaen | G4: เนาวรัตน์ บุญช่วย | H4: B214 | I4: 0829469915
F5: Origin Place Khonkaen | G5: อมิตรา อับดุลเลาะห์ | H5: B232 | I5: 0649804570
F6: Origin Place Khonkaen | G6: จันทร์จิรา เชษฐา | H6: B234 | I6: 0928387525
F7: Origin Place Khonkaen | G7: งามตา แพรงาม | H7: B236 | I7: 0956577481
F8: Origin Place Khonkaen | G8: สุรีย์ณา ปลายนา | H8: B301 | I8: 0642466644
F9: Origin Place Khonkaen | G9: เขมรา จีนหวาด | H9: B303 | I9: 0830565882
F10: Origin Place Khonkaen | G10: จงจิตร พิเศษฤทธิ์ | H10: B306 | I10: 0812550608
F11: Origin Place Khonkaen | G11: ลิขิตพงษ์ สามล | H11: B309 | I11: 0960401505
F12: Origin Place Khonkaen | G12: วนิดา สอนวงษ์ | H12: B311 | I12: "0839700988
F13: Origin Place Khonkaen | G13: อนาวินท์ อิงอนุรักษ์สกุล | H13: B312 | I13: 0919155263
G14: นฤมล ยำพะวา | H14: B313 | I14: 0924716999
G15: แพรชมภู วังศกาญจน์ | H15: B314 | I15: 0941936496
G16: ชนนิกานต์ ศรีคำรุณ | H16: B315 | I16: 0942299669
G17: เนตรนภา เนตรภักดี | H17: B319 | I17: 0896055578
G18: กิตติยา ทองสวัสดิ์ | H18: B327 | I18: 0858290533
G19: วีรภัทร นามสวน | H19: B328 | I19: 0909907782
G20: วราพร แผลงฤทธิ์ | H20: B329 | I20: 0955572800
G21: สุรางคนางค์ บำเพ็ญผล | H21: B330 | I21: 0879857271
G22: อานนท์ โมหะหมัดบาราเฮม | H22: B331 | I22: 0909726575
G23: สุวิทย์ วรสิทธิ์ | H23: B332 | I23: 0819171703
G24: มนัฌยา ดอกดวง | H24: B334 | I24: 0614540988
G25: วศิน ภัทรภาณุ | H25: B336 | I25: 0816981919
... G27: มลทิพย์ สีมันตะ | H27: B403 | I27: 0954369194
G28: ธัญชนก สันทนาประสิทธิ์ | H28: B406
G29: สลักจิต คงแสงทอง | H29: B409
G30: กรรณิการ์ หู้เต็ม | H30: B411
G31: กรรณิการ์ หู้เต็ม | H31: B412
G32: กษิดิศ ลีละสกุลมีเกียรติ | H32: B420
G33: ชนนิกานต์ ศรีคำรุณ | H33: B422
G34: วนิดา สอนวงษ์ | H34: B428
G35: ศรีสุดา สกุลเชื้อ | H35: B429
G36: วชิระ เจริญรื่น | H36: B430
G37: รังสิมา เอมสาน | H37: B431
G38: SEOK JUN MOON
G39: ฐิติกา พลางกูร
A50: 48 | B50: 25284 | D50: หาเอง | E50: Retail | F50: After you Pattaya | G50: After you | I50: - | L50: 500000 | N50: AUN | O50: ต้องติดตามต่อ | P50: 46120 | Q50: ปรับแบบรอส่งประเมินราคา
B51: 25284 | D51: หาเอง | E51: Hotel | F51: The sky vile rooftop. Sukumvit 24 | G51: คุณสมศักดิ์ cm | L51: 3000000 | N51: AUN | O51: ต้องติดตามต่อ | P51: 46120 | Q51: รอปรับ BOQ จาก CM
...

Sheet Ying
B1: SALES : YING
B2: **** WEEKLY REPORT : รายงานการทำงานรายสัปดาห์ ระบุการทำงานเกี่ยวกับ ลูกค้าใหม่ที่ยังไม่จอง และ ลูกค้าใน Backlog + งานอื่นๆที่ทำอยู่ ****
I4: สรุปรายวัน
B5: วันที่ | C5: โครงการ | D5: เลขห้อง | E5: ประเภทลูกค้า | F5: สถานะงาน | G5: เสนอราคา/คาดการ(บาท) | H5: รายละเอียด | I5: LEAD ใหม่ วันนี้ (ราย) | J5: ยอดขายใหม่วันนี้ (ราย) | K5: มูลค่าแพ็คเกจที่จองวันนี้ (บาท) | L5: จำนวนเงินจองมัดจำ วันนี้ (บาท) | M5: ยอดชำระ 50/100% ก่อนตกแต่ง วันนี้ (ราย) | N5: ยอดชำระ 50/100% ก่อนตกแต่ง วันนี้ (บาท)
B6: APR
B7: 46116 | C7: Origin Play Bangkunnon | D7: 2301 | E7: คุยลูกค้าใหม่ | F7: ไม่ซื้อแล้ว | G7: 1052000 | H7: เสนอราคาแล้ว ไม่สนใจ | I7: 9 | J7: 1 | K7: =G14 -> 350000 | L7: 20000 | M7: - | N7: -
C8: Knights Bridge Space Sukhumvit-Rama4 | D8: 1812 | E8: คุยลูกค้าใหม่ | F8: ไม่ซื้อแล้ว | G8: 100000 | H8: เสนอราคาแล้ว ไม่สนใจ จะแต่งห้องเอง
C9: Aspire Onnuch station | D9: 335 | E9: คุยลูกค้าใหม่ | F9: ไม่ซื้อแล้ว | G9: 100000 | H9: เสนอราคาแล้ว ไม่สนใจ จะแต่งห้องเอง
C10: Park Origin Thonglor | D10: B2513 | E10: คุยลูกค้าใหม่ | F10: ไม่ซื้อแล้ว | G10: 300000 | H10: ส่งใบเสนอราคาแล้ว / ไม่สนใจ
C11: Origin Plug&Play Sirindhorn Station | D11: B2402 | E11: คุยลูกค้าใหม่ | F11: ไม่ซื้อแล้ว | G11: 200000 | H11: ส่งใบเสนอราคาแล้ว / ไม่สนใจ
C12: Park Origin Thonglor | D12: B4008 | E12: คุยลูกค้าใหม่ | F12: ไม่ซื้อแล้ว | G12: 200000 | H12: หา ผรมเอง
C13: Origin Play Bangkunnon | D13: 919 | E13: คุยลูกค้าใหม่ | F13: ไม่ซื้อแล้ว | G13: 15000 | H13: เสนอราคาฟิลมเพิ่ม / ไม่สนใจ
C14: Origin Place Bangna | D14: 532 | E14: คุยลูกค้าใหม่ | F14: จองสิทธิ์ | G14: 350000 | H14: เสนอ ราคา ลูกค้าจองออกแบบ
C15: Plug ang Play Srinakarin | D15: 1615 | E15: คุยลูกค้าใหม่ | F15: กำลังคุย | G15: 22100 | H15: ส่งใบเสนอราคาแล้ว / รอตัดสินใจ
C16: Origin Play Bangkhunnon | D16: 12A03 | E16: ลูกค้าในBacklog | F16: จ่าย 50% | G16: 310930 | H16: นัดลูกค้าตรวจรับงาน รับชำระงวดสุดท้าย
C17: Origin Play Bangkhunnon | D17: 812 | E17: ลูกค้าในBacklog | F17: จ่าย 50% | G17: 167620 | H17: นัดลูกค้าตรวจรับงาน รับชำระงวดสุดท้าย
B18: 46117 | C18: Origin Play Bangkhunnon | D18: 1909 | E18: ลูกค้าในBacklog | F18: จ่าย 50% | G18: 383710 | H18: รับชำระ ก่อนตกแต่ง 50% | I18: 2 | J18: - | K18: - | L18: - | M18: 1 | N18: =G18 -> 383710
C19: Origin Play Bangkhunnon | D19: 1418 | E19: ลูกค้าในBacklog | F19: จองสิทธิ์ | G19: 26300 | H19: นัดคุุยรีควายเม้นต์
C20: Origin Play Bangkhunnon | D20: 802 | E20: คุยลูกค้าใหม่ | F20: กำลังคุย | G20: 19610 | H20: นัดเลือกม่าน
C21: Origin Play Bangkhunnon | D21: 2707 | E21: ลูกค้าในBacklog | F21: จองสิทธิ์ | G21: 350000 | H21: นัด คุยบรีฟออกแบบ เพื่อปรับแบบ
C22: Origin Place Bangna | D22: 532 | E22: ลูกค้าในBacklog | F22: จองสิทธิ์ | G22: 350000 | H22: คุยบรีฟออกแบบ / เสนอแบบเฟอร์นิเจอร์เพิ่มเติม
C23: Origin Play Bangkhunnon | D23: 2207 | E23: ลูกค้าในBacklog | F23: จองสิทธิ์ | G23: 220000 | H23: นัด คุยแบบครั้งสุดท้าย และ สรุปรายการตกแต่ง เลือกม่าน
C24: Origin Place Bangna | D24: 710 | E24: คุยลูกค้าใหม่ | F24: กำลังคุย | G24: 24400 | H24: เสนอราคาม่าน / รอตัดสินใจ
B25: 46120 | C25: Origin Place Bangna | D25: 810 | E25: คุยลูกค้าใหม่ | F25: กำลังคุย | G25: 24400 | H25: เสนอราคาม่าน / รอตัดสินใจ | I25: 1 | J25: - | K25: - | L25: - | M25: - | N25: -
C26: Origin Play Bangkhunnon | D26: 1703 | E26: ลูกค้าในBacklog | F26: จ่าย 100%ก่อนตกแต่ง | G26: 28000 | H26: นัดส่งมอบงาน
C27: Origin Play Bangkhunnon | D27: 919 | E27: ลูกค้าในBacklog | F27: จ่าย 100%ก่อนตกแต่ง | G27: 16600 | H27: นัดส่งมอบงาน
C28: Prodigy | D28: 642 | E28: ลูกค้าในBacklog | F28: จองสิทธิ์ | G28: 450000 | H28: นัดวัดที่หน้างาน
B29: 46122 | C29: Park Origin Thonglor | D29: C4207 | E29: ลูกค้าในBacklog | F29: จ่าย 100%ก่อนตกแต่ง | G29: 172000 | H29: ลค นัดดูความคืบหน้า | I29: 1 | J29: - | K29: - | L29: - | M29: - | N29: -
C30: KNB space SK- rama 4 | D30: 2008 | E30: ลูกค้าในBacklog | F30: จ่าย 50% | G30: 735440 | H30: เลือกม่าน ที่โครงการ
C31: Origin Place Bangna | D31: 708 | E31: คุยลูกค้าใหม่ | F31: กำลังคุย | G31: 88250 | H31: นัดคุยบรีฟงานตกแต่ง วัดพื้นที่
B32: 46123 | C32: Origin Play Bangkhunnon | D32: 1418 | E32: ลูกค้าในBacklog | F32: จองสิทธิ์ | G32: 26300 | H32: คุุยลคปรับใบเสนอราคา | I32: - | J32: - | K32: - | L32: - | M32: - | N32: -
C33: ออริจิ้น บางแค | D33: A228 | E33: ลูกค้าในBacklog | F33: จองสิทธิ์ | G33: 108000 | H33: คุุยลคปรับใบเสนอราคา
C34: Place bangna | D34: 532 | E34: ลูกค้าในBacklog | F34: จองสิทธิ์ | G34: 350000 | H34: ทำบรีฟออกแบบให้ทีมออกแบบ
B35: 46124 | C35: Origin Play Bangkhunnon | D35: 2513 | E35: ลูกค้าในBacklog | F35: จองสิทธิ์ | G35: 26000 | H35: ตามลูกค้ามาเลือกม่าน / เสนอแพ็คเพิ่ม | I35: - | J35: - | K35: - | L35: - | M35: - | N35: -
C36: Origin Play Bangkhunnon | D36: 2707 | E36: ลูกค้าในBacklog | F36: จองสิทธิ์ | G36: 350000 | H36: ตามคุยรับบรีฟเพิ่มเติม
C37: Origin Place Bangna | D37: 1239 | E37: ลูกค้าในBacklog | F37: จองสิทธิ์ | G37: 450000 | H37: ตามอัพเดต ความคืบหน้า การเข้างาน
B38: 46132 | C38: Origin Place Bangna | D38: 708 | E38: ลูกค้าใหม่ตามต่อ | F38: กำลังคุย | G38: 88250 | H38: ทำใบเสนอราคา | I38: - | J38: - | K38: - | L38: - | M38: 1 | N38: 26300
C39: Place bangna | D39: 532 | E39: ลูกค้าในBacklog | F39: จองสิทธิ์ | G39: 350000 | H39: ตามคุุยบรีฟเพิ่มเติม
C40: Origin Place Bangna | D40: 1239 | E40: ลูกค้าในBacklog | F40: จ่าย 50% | G40: 450000 | H40: ตามอัพเดต ความคืบหน้า
C41: Origin Play Bangkhunnon | D41: 1418 | E41: ลูกค้าในBacklog | F41: จ่าย 100%ก่อนตกแต่ง | G41: 26300 | H41: ทำใบเสนอราคา / ตามนัดเก็บเงิน
...

Sheet ชีต32

Sheet Pang
