Workbook

Sheet SUM
A2: คาดส่งงาน | B2: คาดส่งงาน | D2: Project | E2: Room | F2: Type | G2: Area | H2: Project | N2: Project Timeline | P2: Timeline เปิด PO | U2: Status | V2: Type of work | AB2: TEAM | AE2: Note
A3: Q (Auto) | B3: เดือน | D3: name | E3: Number | F3: Function | G3: Sq.m. | H3: Revenue | I3: มูลค่าจัดจ้างซัพ | J3: Cost ประมาณการณ์ | K3: กำไร | L3: GP | M3: work type | N3: sale ส่งเมล | O3: สัญญาลูกค้า | P3: KPI (14 day) | Q3: เปิดPO ครบทุกหมวด | R3: LATE (Day) | T3: LATE | U3: of work | V3: Built-In | W3: Loose Furniture | X3: Wallpaper | Y3: Curtain | Z3: Prop | AA3: Cleaning | AB3: Co-Designer | AC3: Sale | AD3: Contractor | AE3: Description
G4: =Sum(G15:G46) -> 0 | H4: =SUM(H15:H46) -> 38272055 | I4: =SUM(I15:I46) -> 7606375.5 | J4: =SUM(J15:J46) -> 30156180 | K4: =SUM(K15:K46) -> 8314656.3
A5: {="Q" & INT((MATCH(B5, {"ม.ค.-26","ก.พ.-26","มี.ค.-26","เม.ย.-26","พ.ค.-26","มิ.ย.-26","ก.ค.-26","ส.ค.-26","ก.ย.-26","ต.ค.-26","พ.ย.-26","ธ.ค.-26"}, 0) + 2) / 3)} -> Q3 | B5: =TEXT(O5, "mmm-yy") -> ก.ค.-26 | D5: ='The Origin Sukhumvit-Praksa'!B19 -> The Origin Sukhumvit-Praksa | E5: =VLOOKUP($D$5,'The Origin Sukhumvit-Praksa'!$B$19:$O$19,2) -> Room 2514 | F5: =VLOOKUP($D$5,'The Origin Sukhumvit-Praksa'!$B$19:$O$19,2) -> Room 2514 | G5: =VLOOKUP($D$5,'The Origin Sukhumvit-Praksa'!$B$19:$O$19,2) -> Room 2514 | H5: ='The Origin Sukhumvit-Praksa'!I19 -> 9345.7944 | I5: ='The Origin Sukhumvit-Praksa'!J19 -> 8000 | J5: ='The Origin Sukhumvit-Praksa'!M19 -> 7800 | K5: =H5-I5 -> 1345.7944 | L5: =K5/H5 -> 0.144 | M5: B2C | N5: 46201 | O5: 46233 | P5: =N5+14 -> 46215 | Q5: 46218 | R5: =P5-Q5 -> -3 | S5: FALSE | T5: =IFS(S5=true,"แล้วเสร็จ",R5<1,"เลยกำหนด", R5>=1,"อยู่ในกำหนด") -> เลยกำหนด | U5: CONSTRUCTION | V5: FALSE | W5: FALSE | X5: FALSE | Y5: FALSE | Z5: FALSE | AA5: FALSE | AC5: P'PANG
S6: FALSE | V6: FALSE | W6: FALSE | X6: FALSE | Y6: FALSE | Z6: FALSE | AA6: FALSE
A7: {="Q" & INT((MATCH(B7, {"ม.ค.-26","ก.พ.-26","มี.ค.-26","เม.ย.-26","พ.ค.-26","มิ.ย.-26","ก.ค.-26","ส.ค.-26","ก.ย.-26","ต.ค.-26","พ.ย.-26","ธ.ค.-26"}, 0) + 2) / 3)} -> Q3 | B7: =TEXT(O7, "mmm-yy") -> ส.ค.-26 | D7: ='Origin Plug & Play Sirindhorn S'!B11 -> Origin Plug & Play Sirindhorn Station | E7: ='Origin Plug & Play Sirindhorn S'!C11 -> Room B1009 | F7: =VLOOKUP($D$5,'The Origin Sukhumvit-Praksa'!$B$19:$O$19,2) -> Room 2514 | G7: =VLOOKUP($D$5,'The Origin Sukhumvit-Praksa'!$B$19:$O$19,2) -> Room 2514 | H7: ='Origin Plug & Play Sirindhorn S'!I11 -> 138317.76 | I7: ='Origin Plug & Play Sirindhorn S'!J11 -> 90654.21 | J7: ='Origin Plug & Play Sirindhorn S'!M11 -> 96000 | K7: =H7-J7 -> 42317.757 | L7: =K7/H7 -> 0.30594595 | M7: B2C | N7: 46232 | O7: 46265 | P7: =N7+14 -> 46246 | R7: =P7-Q7 -> 46246 | S7: FALSE | T7: =IFS(S7=true,"แล้วเสร็จ",R7<1,"เลยกำหนด", R7>=1,"อยู่ในกำหนด") -> อยู่ในกำหนด | U7: CONSTRUCTION | V7: FALSE | W7: FALSE | X7: FALSE | Y7: FALSE | Z7: FALSE | AA7: FALSE | AC7: P'PANG
S8: FALSE | V8: FALSE | W8: FALSE | X8: FALSE | Y8: FALSE | Z8: FALSE | AA8: FALSE
A9: {="Q" & INT((MATCH(B9, {"ม.ค.-26","ก.พ.-26","มี.ค.-26","เม.ย.-26","พ.ค.-26","มิ.ย.-26","ก.ค.-26","ส.ค.-26","ก.ย.-26","ต.ค.-26","พ.ย.-26","ธ.ค.-26"}, 0) + 2) / 3)} -> Q3 | B9: =TEXT(O9, "mmm-yy") -> ส.ค.-26 | D9: ='Origin Place Bangna'!B21 -> Origin Place Bangna | E9: ='Origin Place Bangna'!C21 -> Room 532 | F9: =VLOOKUP($D$5,'The Origin Sukhumvit-Praksa'!$B$19:$O$19,2) -> Room 2514 | G9: =VLOOKUP($D$5,'The Origin Sukhumvit-Praksa'!$B$19:$O$19,2) -> Room 2514 | H9: ='Origin Place Bangna'!I21 -> 185887.85 | I9: ='Origin Place Bangna'!J21 -> 84656.08 | J9: ='Origin Place Bangna'!M21 -> 138550 | K9: =H9-I9 -> 101231.77 | L9: =K9/H9 -> 0.54458519 | M9: B2C | N9: 46188 | O9: 46265 | P9: =N9+14 -> 46202 | Q9: 46195 | R9: =P9-Q9 -> 7 | S9: FALSE | T9: =IFS(S9=true,"แล้วเสร็จ",R9<1,"เลยกำหนด", R9>=1,"อยู่ในกำหนด") -> อยู่ในกำหนด | U9: CONSTRUCTION | V9: FALSE | W9: FALSE | X9: FALSE | Y9: FALSE | Z9: FALSE | AA9: FALSE | AC9: P'PANG
S10: FALSE | V10: FALSE | W10: FALSE | X10: FALSE | Y10: FALSE | Z10: FALSE | AA10: FALSE
A11: ="Q" & INT((MATCH(B11, {"ม.ค.-26","ก.พ.-26","มี.ค.-26","เม.ย.-26","พ.ค.-26","มิ.ย.-26","ก.ค.-26","ส.ค.-26","ก.ย.-26","ต.ค.-26","พ.ย.-26","ธ.ค.-26"}, 0) + 2) / 3) -> Q3 | B11: =TEXT(O11, "mmm-yy") -> ก.ค.-26 | D11: ='Origin Place Phetkasem'!B21 -> Origin Place Phetkasem | E11: ='Origin Place Phetkasem'!C21 -> Room 919 | H11: ='Origin Place Phetkasem'!I21 -> 51028.037 | I11: ='Origin Place Phetkasem'!J21 -> 32175 | J11: ='Origin Place Phetkasem'!M21 -> 37500 | K11: =H11-I11 -> 18853.037 | L11: =K11/H11 -> 0.36946429 | M11: B2C | N11: 46201 | O11: 46233 | P11: =N11+14 -> 46215 | Q11: 46218 | R11: =P11-Q11 -> -3 | S11: FALSE | T11: =IFS(S11=true,"แล้วเสร็จ",R11<1,"เลยกำหนด", R11>=1,"อยู่ในกำหนด") -> เลยกำหนด | U11: CONSTRUCTION | V11: FALSE | W11: FALSE | X11: FALSE | Y11: FALSE | Z11: FALSE | AA11: FALSE | AC11: P'PANG
A12: ="Q" & INT((MATCH(B12, {"ม.ค.-26","ก.พ.-26","มี.ค.-26","เม.ย.-26","พ.ค.-26","มิ.ย.-26","ก.ค.-26","ส.ค.-26","ก.ย.-26","ต.ค.-26","พ.ย.-26","ธ.ค.-26"}, 0) + 2) / 3) -> Q3 | B12: =TEXT(O12, "mmm-yy") -> ก.ค.-26 | D12: ='Origin Place Phetkasem'!B38 -> Origin Place Phetkasem | E12: ='Origin Place Phetkasem'!C38 -> Room 818 | H12: ='Origin Place Phetkasem'!I38 -> 27644.86 | I12: ='Origin Place Phetkasem'!J38 -> 16775 | J12: ='Origin Place Phetkasem'!M38 -> 20025 | K12: =H12-I12 -> 10869.86 | L12: =K12/H12 -> 0.39319642 | M12: B2C | N12: 46201 | O12: 46233 | P12: =N12+14 -> 46215 | Q12: 46218 | R12: =P12-Q12 -> -3 | S12: FALSE | T12: =IFS(S12=true,"แล้วเสร็จ",R12<1,"เลยกำหนด", R12>=1,"อยู่ในกำหนด") -> เลยกำหนด | U12: CONSTRUCTION | V12: FALSE | W12: FALSE | X12: FALSE | Y12: FALSE | Z12: FALSE | AA12: FALSE | AC12: P'PANG
A13: ="Q" & INT((MATCH(B13, {"ม.ค.-26","ก.พ.-26","มี.ค.-26","เม.ย.-26","พ.ค.-26","มิ.ย.-26","ก.ค.-26","ส.ค.-26","ก.ย.-26","ต.ค.-26","พ.ย.-26","ธ.ค.-26"}, 0) + 2) / 3) -> Q3 | B13: =TEXT(O13, "mmm-yy") -> ก.ย.-26 | D13: ='Origin Place Phetkasem'!B54 -> Origin Place Phetkasem | E13: ='Origin Place Phetkasem'!C54 -> Room 502 | H13: ='Origin Place Phetkasem'!I54 -> 457943.93 | I13: ='Origin Place Phetkasem'!J39 | J13: ='Origin Place Phetkasem'!M54 -> 332219.63 | K13: =H13-I13 -> 457943.93 | L13: =K13/H13 -> 1 | M13: B2C | N13: 46247 | O13: 46295 | P13: =N13+14 -> 46261 | Q13: 46260 | R13: =P13-Q13 -> 1 | S13: FALSE | T13: =IFS(S13=true,"แล้วเสร็จ",R13<1,"เลยกำหนด", R13>=1,"อยู่ในกำหนด") -> อยู่ในกำหนด | U13: CONSTRUCTION | V13: FALSE | W13: FALSE | X13: FALSE | Y13: FALSE | Z13: FALSE | AA13: FALSE | AC13: P'PANG
S14: FALSE | V14: FALSE | W14: FALSE | X14: FALSE | Y14: FALSE | Z14: FALSE | AA14: FALSE
A15: ="Q" & INT((MATCH(B15, {"ม.ค.-26","ก.พ.-26","มี.ค.-26","เม.ย.-26","พ.ค.-26","มิ.ย.-26","ก.ค.-26","ส.ค.-26","ก.ย.-26","ต.ค.-26","พ.ย.-26","ธ.ค.-26"}, 0) + 2) / 3) -> Q3 | B15: =TEXT(O15, "mmm-yy") -> ก.ค.-26 | D15: ='Origin Play Bangkhunnon'!B19 -> Origin Play Bangkhunnon | E15: =VLOOKUP(D15,'Origin Play Bangkhunnon'!B19:O19,2) -> Room 1809 | H15: ='Origin Play Bangkhunnon'!I19 -> 26000 | I15: ='Origin Play Bangkhunnon'!J19 -> 14000 | J15: ='Origin Play Bangkhunnon'!M19 -> 17000 | K15: =H15-I15 -> 12000 | L15: =K15/H15 -> 0.46153846 | M15: B2C | N15: 46201 | O15: 46219 | P15: =N15+14 -> 46215 | Q15: 46203 | R15: =P15-Q15 -> 12 | S15: FALSE | T15: =IFS(S15=true,"แล้วเสร็จ",R15<1,"เลยกำหนด", R15>=1,"อยู่ในกำหนด") -> อยู่ในกำหนด | U15: ส่งมอบแล้ว | V15: FALSE | W15: FALSE | X15: FALSE | Y15: FALSE | Z15: FALSE | AA15: FALSE | AC15: P'YING
A16: ="Q" & INT((MATCH(B16, {"ม.ค.-26","ก.พ.-26","มี.ค.-26","เม.ย.-26","พ.ค.-26","มิ.ย.-26","ก.ค.-26","ส.ค.-26","ก.ย.-26","ต.ค.-26","พ.ย.-26","ธ.ค.-26"}, 0) + 2) / 3) -> Q3 | B16: =TEXT(O16, "mmm-yy") -> ก.ค.-26 | D16: ='Origin Play Bangkhunnon'!B34 -> Origin Play Bangkhunnon | E16: ='Origin Play Bangkhunnon'!C34 -> Room 901 | F16: =VLOOKUP($D$24,'The Origin Bangkae'!$B$19:$O$19,2) -> Room C310 | G16: =VLOOKUP($D$24,'The Origin Bangkae'!$B$19:$O$19,2) -> Room C310 | H16: ='Origin Play Bangkhunnon'!I34 -> 167514.02 | I16: ='Origin Play Bangkhunnon'!J34 -> 114840.88 | J16: ='Origin Play Bangkhunnon'!M34 -> 0 | K16: =H16-I16 -> 52673.139 | L16: =K16/H16 -> 0.31444018 | M16: B2C | N16: 46201 | O16: 46233 | P16: =N16+14 -> 46215 | Q16: 46203 | R16: =P16-Q16 -> 12 | S16: FALSE | T16: =IFS(S16=true,"แล้วเสร็จ",R16<1,"เลยกำหนด", R16>=1,"อยู่ในกำหนด") -> อยู่ในกำหนด | U16: ส่งมอบแล้ว | V16: FALSE | W16: FALSE | X16: FALSE | Y16: FALSE | Z16: FALSE | AA16: FALSE | AC16: P'PANG
A17: ="Q" & INT((MATCH(B17, {"ม.ค.-26","ก.พ.-26","มี.ค.-26","เม.ย.-26","พ.ค.-26","มิ.ย.-26","ก.ค.-26","ส.ค.-26","ก.ย.-26","ต.ค.-26","พ.ย.-26","ธ.ค.-26"}, 0) + 2) / 3) -> Q3 | B17: =TEXT(O17, "mmm-yy") -> ก.ค.-26 | D17: ='Origin Play Bangkhunnon'!B41 -> Origin Play Bangkhunnon | E17: ='Origin Play Bangkhunnon'!C41 -> Room 2324 | H17: ='Origin Play Bangkhunnon'!I41 -> 5140.1869 | I17: ='Origin Play Bangkhunnon'!J41 -> 3378.88 | J17: ='Origin Play Bangkhunnon'!M41 -> 3366 | K17: =H17-I17 -> 1761.3069 | L17: =K17/H17 -> 0.34265425 | M17: B2C | N17: 46201 | O17: 46219 | P17: =N17+14 -> 46215 | Q17: 46223 | R17: =P17-Q17 -> -8 | S17: FALSE | T17: =IFS(S17=true,"แล้วเสร็จ",R17<1,"เลยกำหนด", R17>=1,"อยู่ในกำหนด") -> เลยกำหนด | U17: CONSTRUCTION | V17: FALSE | W17: FALSE | X17: FALSE | Y17: FALSE | Z17: FALSE | AA17: FALSE | AC17: P'YING
A18: ="Q" & INT((MATCH(B18, {"ม.ค.-26","ก.พ.-26","มี.ค.-26","เม.ย.-26","พ.ค.-26","มิ.ย.-26","ก.ค.-26","ส.ค.-26","ก.ย.-26","ต.ค.-26","พ.ย.-26","ธ.ค.-26"}, 0) + 2) / 3) -> Q3 | B18: =TEXT(O18, "mmm-yy") -> ก.ค.-26 | D18: ='Origin Play Bangkhunnon'!B53 -> Origin Play Bangkhunnon | E18: ='Origin Play Bangkhunnon'!C53 -> Room 1121 | F18: =VLOOKUP($D$24,'The Origin Bangkae'!$B$19:$O$19,2) -> Room C310 | G18: =VLOOKUP($D$24,'The Origin Bangkae'!$B$19:$O$19,2) -> Room C310 | H18: ='Origin Play Bangkhunnon'!I53 -> 109644.86 | I18: ='Origin Play Bangkhunnon'!J53 -> 60350 | J18: ='Origin Play Bangkhunnon'!M53 -> 84961.25 | K18: =H18-I18 -> 49294.86 | L18: =K18/H18 -> 0.4495866 | M18: B2C | N18: 46201 | O18: 46233 | P18: =N18+14 -> 46215 | Q18: 46223 | R18: =P18-Q18 -> -8 | S18: FALSE | T18: =IFS(S18=true,"แล้วเสร็จ",R18<1,"เลยกำหนด", R18>=1,"อยู่ในกำหนด") -> เลยกำหนด | U18: CONSTRUCTION | V18: TRUE | W18: FALSE | X18: FALSE | Y18: TRUE | Z18: FALSE | AA18: FALSE | AC18: P'PANG
A19: ="Q" & INT((MATCH(B19, {"ม.ค.-26","ก.พ.-26","มี.ค.-26","เม.ย.-26","พ.ค.-26","มิ.ย.-26","ก.ค.-26","ส.ค.-26","ก.ย.-26","ต.ค.-26","พ.ย.-26","ธ.ค.-26"}, 0) + 2) / 3) -> Q3 | B19: =TEXT(O19, "mmm-yy") -> ก.ค.-26 | D19: ='Origin Play Bangkhunnon'!B70 -> Origin Play Bangkhunnon | E19: ='Origin Play Bangkhunnon'!C70 -> Room 1621 | F19: =VLOOKUP($D$24,'The Origin Bangkae'!$B$19:$O$19,2) -> Room C310 | G19: =VLOOKUP($D$24,'The Origin Bangkae'!$B$19:$O$19,2) -> Room C310 | H19: ='Origin Play Bangkhunnon'!I70 -> 23065.421 | I19: ='Origin Play Bangkhunnon'!J70 -> 15000 | J19: ='Origin Play Bangkhunnon'!M70 -> 16000 | K19: =H19-I19 -> 8065.4206 | L19: =K19/H19 -> 0.34967585 | M19: B2C | N19: 46201 | O19: 46233 | P19: =N19+14 -> 46215 | Q19: 46209 | R19: =P19-Q19 -> 6 | S19: FALSE | T19: =IFS(S19=true,"แล้วเสร็จ",R19<1,"เลยกำหนด", R19>=1,"อยู่ในกำหนด") -> อยู่ในกำหนด | U19: CONSTRUCTION | V19: TRUE | W19: FALSE | X19: FALSE | Y19: TRUE | Z19: FALSE | AA19: FALSE | AC19: P'PANG
A20: ="Q" & INT((MATCH(B20, {"ม.ค.-26","ก.พ.-26","มี.ค.-26","เม.ย.-26","พ.ค.-26","มิ.ย.-26","ก.ค.-26","ส.ค.-26","ก.ย.-26","ต.ค.-26","พ.ย.-26","ธ.ค.-26"}, 0) + 2) / 3) -> Q3 | B20: =TEXT(O20, "mmm-yy") -> ส.ค.-26 | D20: ='Origin Play Bangkhunnon'!B72 -> Origin Play Bangkhunnon | E20: ='Origin Play Bangkhunnon'!C72 -> Room 1601 | H20: ='Origin Play Bangkhunnon'!I87 -> 33532.71 | I20: ='Origin Play Bangkhunnon'!J87 -> 7000 | J20: ='Origin Play Bangkhunnon'!M87 -> 23600 | K20: =H20-J20 -> 9932.7103 | L20: =K20/H20 -> 0.29620959 | M20: B2C | N20: 46233 | O20: 46264 | P20: =N20+14 -> 46247 | Q20: 46234 | R20: =P20-Q20 -> 13 | S20: FALSE | T20: =IFS(S20=true,"แล้วเสร็จ",R20<1,"เลยกำหนด", R20>=1,"อยู่ในกำหนด") -> อยู่ในกำหนด | U20: CONSTRUCTION | V20: TRUE | W20: FALSE | X20: FALSE | Y20: TRUE | Z20: FALSE | AA20: FALSE | AC20: P'HACK
S21: FALSE | V21: FALSE | W21: FALSE | X21: FALSE | Y21: FALSE | Z21: FALSE | AA21: FALSE
A22: {="Q" & INT((MATCH(B22, {"ม.ค.-26","ก.พ.-26","มี.ค.-26","เม.ย.-26","พ.ค.-26","มิ.ย.-26","ก.ค.-26","ส.ค.-26","ก.ย.-26","ต.ค.-26","พ.ย.-26","ธ.ค.-26"}, 0) + 2) / 3)} -> Q3 | B22: =TEXT(O22, "mmm-yy") -> ส.ค.-26 | D22: ='IP Program Origin Place Bangna'!B46 -> Origin Place Bangna | E22: ='IP Program Origin Place Bangna'!C46 -> IP Program | H22: ='IP Program Origin Place Bangna'!J46 -> 36618504 | I22: ='IP Program Origin Place Bangna'!K46 -> 6960379.3 | J22: =H22*0.8 -> 29294803 | K22: =H22-J22 -> 7323700.7 | L22: =K22/H22 -> 0.2 | M22: B2C | N22: 46233 | O22: 46264 | P22: =N22+14 -> 46247 | Q22: 46234 | R22: =P22-Q22 -> 13 | S22: FALSE | T22: =IFS(S22=true,"แล้วเสร็จ",R22<1,"เลยกำหนด", R22>=1,"อยู่ในกำหนด") -> อยู่ในกำหนด | U22: CONSTRUCTION | V22: TRUE | W22: FALSE | X22: FALSE | Y22: TRUE | Z22: FALSE | AA22: FALSE | AC22: P'HACK
S23: FALSE | V23: FALSE | W23: FALSE | X23: FALSE | Y23: FALSE | Z23: FALSE | AA23: FALSE
A24: ="Q" & INT((MATCH(B24, {"ม.ค.-26","ก.พ.-26","มี.ค.-26","เม.ย.-26","พ.ค.-26","มิ.ย.-26","ก.ค.-26","ส.ค.-26","ก.ย.-26","ต.ค.-26","พ.ย.-26","ธ.ค.-26"}, 0) + 2) / 3) -> Q3 | B24: =TEXT(O24, "mmm-yy") -> ก.ค.-26 | D24: ='The Origin Bangkae'!B19 -> The Origin Bangkae | E24: ='The Origin Bangkae'!C19 -> Room C310 | F24: =VLOOKUP($D$24,'The Origin Bangkae'!$B$19:$O$19,2) -> Room C310 | G24: =VLOOKUP($D$24,'The Origin Bangkae'!$B$19:$O$19,2) -> Room C310 | H24: ='The Origin Bangkae'!I19 -> 7242.9907 | I24: ='The Origin Bangkae'!J19 -> 4060.7477 | J24: ='The Origin Bangkae'!M19 -> 4345 | K24: =H24-I24 -> 3182.243 | L24: =K24/H24 -> 0.43935484 | M24: B2C | N24: 46201 | O24: 46233 | P24: =N24+14 -> 46215 | Q24: 46209 | R24: =P24-Q24 -> 6 | S24: FALSE | T24: =IFS(S24=true,"แล้วเสร็จ",R24<1,"เลยกำหนด", R24>=1,"อยู่ในกำหนด") -> อยู่ในกำหนด | U24: CONSTRUCTION | V24: FALSE | W24: FALSE | X24: FALSE | Y24: FALSE | Z24: FALSE | AA24: FALSE | AC24: P'PANG
A25: ="Q" & INT((MATCH(B25, {"ม.ค.-26","ก.พ.-26","มี.ค.-26","เม.ย.-26","พ.ค.-26","มิ.ย.-26","ก.ค.-26","ส.ค.-26","ก.ย.-26","ต.ค.-26","พ.ย.-26","ธ.ค.-26"}, 0) + 2) / 3) -> Q3 | B25: =TEXT(O25, "mmm-yy") -> ก.ค.-26 | D25: ='The Origin Bangkae'!B21 -> The Origin Bangkae | E25: ='The Origin Bangkae'!C21 -> Room A202 | F25: =VLOOKUP($D$24,'The Origin Bangkae'!$B$19:$O$19,2) -> Room C310 | G25: =VLOOKUP($D$24,'The Origin Bangkae'!$B$19:$O$19,2) -> Room C310 | H25: ='The Origin Bangkae'!I36 -> 4672.8972 | I25: ='The Origin Bangkae'!J36 -> 2200 | J25: ='The Origin Bangkae'!M36 -> 2200 | K25: =H25-I25 -> 2472.8972 | L25: =K25/H25 -> 0.5292 | M25: B2C | N25: 46208 | O25: 46220 | P25: =N25+14 -> 46222 | Q25: 46209 | R25: =P25-Q25 -> 13 | S25: FALSE | T25: =IFS(S25=true,"แล้วเสร็จ",R25<1,"เลยกำหนด", R25>=1,"อยู่ในกำหนด") -> อยู่ในกำหนด | U25: CONSTRUCTION | V25: FALSE | W25: FALSE | X25: FALSE | Y25: FALSE | Z25: FALSE | AA25: FALSE | AC25: P'PANG
S26: FALSE | V26: FALSE | W26: FALSE | X26: FALSE | Y26: FALSE | Z26: FALSE | AA26: FALSE
A27: {="Q" & INT((MATCH(B27, {"ม.ค.-26","ก.พ.-26","มี.ค.-26","เม.ย.-26","พ.ค.-26","มิ.ย.-26","ก.ค.-26","ส.ค.-26","ก.ย.-26","ต.ค.-26","พ.ย.-26","ธ.ค.-26"}, 0) + 2) / 3)} -> Q3 | B27: =TEXT(O27, "mmm-yy") -> ส.ค.-26 | D27: ='The Origin Kathu - Patong'!B20 -> The Origin Kathu - Patong | E27: ='The Origin Kathu - Patong'!C20 -> Room B418 | F27: =VLOOKUP($D$24,'The Origin Bangkae'!$B$19:$O$19,2) -> Room C310 | G27: =VLOOKUP($D$24,'The Origin Bangkae'!$B$19:$O$19,2) -> Room C310 | H27: ='The Origin Kathu - Patong'!I20 -> 23962.617 | I27: ='The Origin Kathu - Patong'!J20 -> 15240 | J27: ='The Origin Kathu - Patong'!M20 -> 17255 | K27: =H27-I27 -> 8722.6168 | L27: =K27/H27 -> 0.36400936 | M27: B2C | N27: 46223 | O27: 46265 | P27: =N27+14 -> 46237 | Q27: 46227 | R27: =P27-Q27 -> 10 | S27: FALSE | T27: =IFS(S27=true,"แล้วเสร็จ",R27<1,"เลยกำหนด", R27>=1,"อยู่ในกำหนด") -> อยู่ในกำหนด | U27: CONSTRUCTION | V27: FALSE | W27: FALSE | X27: FALSE | Y27: FALSE | Z27: FALSE | AA27: FALSE | AC27: P'PANG
S28: FALSE | V28: FALSE | W28: FALSE | X28: FALSE | Y28: FALSE | Z28: FALSE | AA28: FALSE
A29: ="Q" & INT((MATCH(B29, {"ม.ค.-26","ก.พ.-26","มี.ค.-26","เม.ย.-26","พ.ค.-26","มิ.ย.-26","ก.ค.-26","ส.ค.-26","ก.ย.-26","ต.ค.-26","พ.ย.-26","ธ.ค.-26"}, 0) + 2) / 3) -> Q3 | B29: =TEXT(O29, "mmm-yy") -> ส.ค.-26 | D29: ='The Origin Phahol 57'!B16 -> The Origin Phahol 57 | E29: ='The Origin Phahol 57'!C16 -> Room A402 | F29: =VLOOKUP($D$24,'The Origin Bangkae'!$B$19:$O$19,2) -> Room C310 | G29: =VLOOKUP($D$24,'The Origin Bangkae'!$B$19:$O$19,2) -> Room C310 | H29: ='The Origin Phahol 57'!I16 -> 12336.449 | I29: ='The Origin Kathu - Patong'!J22 | J29: ='The Origin Phahol 57'!M16 -> 7500 | K29: =H29-I29 -> 12336.449 | L29: =K29/H29 -> 1 | M29: B2C | N29: 46223 | O29: 46265 | P29: =N29+14 -> 46237 | Q29: 46227 | R29: =P29-Q29 -> 10 | S29: FALSE | T29: =IFS(S29=true,"แล้วเสร็จ",R29<1,"เลยกำหนด", R29>=1,"อยู่ในกำหนด") -> อยู่ในกำหนด | U29: เสนอราคา | V29: FALSE | W29: FALSE | X29: FALSE | Y29: FALSE | Z29: FALSE | AA29: FALSE | AC29: P'PANG
A30: ="Q" & INT((MATCH(B30, {"ม.ค.-26","ก.พ.-26","มี.ค.-26","เม.ย.-26","พ.ค.-26","มิ.ย.-26","ก.ค.-26","ส.ค.-26","ก.ย.-26","ต.ค.-26","พ.ย.-26","ธ.ค.-26"}, 0) + 2) / 3) -> Q3 | B30: =TEXT(O30, "mmm-yy") -> ส.ค.-26 | D30: ='The Origin Phahol 57'!B30 -> The Origin Phahol 57 | E30: ='The Origin Phahol 57'!C30 -> Room B720 | F30: =VLOOKUP($D$24,'The Origin Bangkae'!$B$19:$O$19,2) -> Room C310 | G30: =VLOOKUP($D$24,'The Origin Bangkae'!$B$19:$O$19,2) -> Room C310 | H30: ='The Origin Phahol 57'!I30 -> 9345.7944 | I30: ='The Origin Kathu - Patong'!J23 | J30: ='The Origin Phahol 57'!M30 -> 5000 | K30: =H30-I30 -> 9345.7944 | L30: =K30/H30 -> 1 | M30: B2C | N30: 46223 | O30: 46265 | P30: =N30+14 -> 46237 | Q30: 46227 | R30: =P30-Q30 -> 10 | S30: FALSE | T30: =IFS(S30=true,"แล้วเสร็จ",R30<1,"เลยกำหนด", R30>=1,"อยู่ในกำหนด") -> อยู่ในกำหนด | U30: เสนอราคา | V30: FALSE | W30: FALSE | X30: FALSE | Y30: FALSE | Z30: FALSE | AA30: FALSE | AC30: P'PANG
S31: FALSE | V31: FALSE | W31: FALSE | X31: FALSE | Y31: FALSE | Z31: FALSE | AA31: FALSE
A32: {="Q" & INT((MATCH(B32, {"ม.ค.-26","ก.พ.-26","มี.ค.-26","เม.ย.-26","พ.ค.-26","มิ.ย.-26","ก.ค.-26","ส.ค.-26","ก.ย.-26","ต.ค.-26","พ.ย.-26","ธ.ค.-26"}, 0) + 2) / 3)} -> Q3 | B32: =TEXT(O32, "mmm-yy") -> ก.ย.-26 | D32: ='Origin Play Bangsaen'!B17 -> Origin Play Bangsaen | E32: ='Origin Play Bangsaen'!C17 -> Room 1218 | F32: =VLOOKUP($D$24,'The Origin Bangkae'!$B$19:$O$19,2) -> Room C310 | G32: =VLOOKUP($D$24,'The Origin Bangkae'!$B$19:$O$19,2) -> Room C310 | H32: ='Origin Play Bangsaen'!I17 -> 401869.16 | I32: ='The Origin Kathu - Patong'!J25 | J32: ='Origin Play Bangsaen'!M17 -> 286940 | K32: =H32-I32 -> 401869.16 | L32: =K32/H32 -> 1 | M32: B2C | N32: 46223 | O32: 46295 | P32: =N32+14 -> 46237 | Q32: 46227 | R32: =P32-Q32 -> 10 | S32: FALSE | T32: =IFS(S32=true,"แล้วเสร็จ",R32<1,"เลยกำหนด", R32>=1,"อยู่ในกำหนด") -> อยู่ในกำหนด | U32: เสนอราคา | V32: FALSE | W32: FALSE | X32: FALSE | Y32: FALSE | Z32: FALSE | AA32: FALSE | AC32: P'PANG
S33: FALSE | V33: FALSE | W33: FALSE | X33: FALSE | Y33: FALSE | Z33: FALSE | AA33: FALSE
A34: ="Q" & INT((MATCH(B34, {"ม.ค.-26","ก.พ.-26","มี.ค.-26","เม.ย.-26","พ.ค.-26","มิ.ย.-26","ก.ค.-26","ส.ค.-26","ก.ย.-26","ต.ค.-26","พ.ย.-26","ธ.ค.-26"}, 0) + 2) / 3) -> Q3 | B34: =TEXT(O34, "mmm-yy") -> ก.ค.-26 | D34: ='Origin Plug & Play E22 Station'!B4 -> Origin Plug & Play E22 Station | E34: ='Origin Plug & Play E22 Station'!C4 -> Room 1833 | H34: ='Origin Plug & Play E22 Station'!I28 -> 130841.12 | I34: ='Origin Plug & Play E22 Station'!J28 -> 66105.756 | J34: ='Origin Plug & Play E22 Station'!M28 -> 61651.7 | K34: =H34-I34 -> 64735.365 | L34: =K34/H34 -> 0.49476315 | M34: B2C | N34: 46201 | O34: 46233 | P34: =N34+14 -> 46215 | Q34: 46204 | R34: =P34-Q34 -> 11 | S34: FALSE | T34: =IFS(S34=true,"แล้วเสร็จ",R34<1,"เลยกำหนด", R34>=1,"อยู่ในกำหนด") -> อยู่ในกำหนด | U34: CONSTRUCTION | V34: FALSE | W34: FALSE | X34: FALSE | Y34: FALSE | Z34: FALSE | AA34: FALSE | AC34: P'PANG
A35: ="Q" & INT((MATCH(B35, {"ม.ค.-26","ก.พ.-26","มี.ค.-26","เม.ย.-26","พ.ค.-26","มิ.ย.-26","ก.ค.-26","ส.ค.-26","ก.ย.-26","ต.ค.-26","พ.ย.-26","ธ.ค.-26"}, 0) + 2) / 3) -> Q3 | B35: =TEXT(O35, "mmm-yy") -> ก.ค.-26 | D35: ='Origin Plug & Play E22 Station'!B40 -> Origin Plug & Play E22 Station | E35: ='Origin Plug & Play E22 Station'!C40 -> Room 1833 | H35: ='Origin Plug & Play E22 Station'!I40 -> 29830 | I35: ='Origin Plug & Play E22 Station'!J40 -> 13000 | J35: ='Origin Plug & Play E22 Station'!M40 -> 13000 | K35: =H35-I35 -> 16830 | L35: =K35/H35 -> 0.56419712 | M35: B2C | N35: 46201 | O35: 46233 | P35: =N35+14 -> 46215 | Q35: 46204 | R35: =P35-Q35 -> 11 | S35: FALSE | T35: =IFS(S35=true,"แล้วเสร็จ",R35<1,"เลยกำหนด", R35>=1,"อยู่ในกำหนด") -> อยู่ในกำหนด | U35: CONSTRUCTION | V35: FALSE | W35: FALSE | X35: FALSE | Y35: FALSE | Z35: FALSE | AA35: FALSE | AC35: P'PANG
A36: ="Q" & INT((MATCH(B36, {"ม.ค.-26","ก.พ.-26","มี.ค.-26","เม.ย.-26","พ.ค.-26","มิ.ย.-26","ก.ค.-26","ส.ค.-26","ก.ย.-26","ต.ค.-26","พ.ย.-26","ธ.ค.-26"}, 0) + 2) / 3) -> Q3 | B36: =TEXT(O36, "mmm-yy") -> ก.ค.-26 | D36: ='Origin Plug & Play E22 Station'!B53 -> Origin Plug & Play E22 Station | E36: ='Origin Plug & Play E22 Station'!C53 -> Room 1833 | H36: ='Origin Plug & Play E22 Station'!I53 -> 8411.215 | I36: ='Origin Plug & Play E22 Station'!J53 -> 6710 | J36: ='Origin Plug & Play E22 Station'!M53 -> 6710 | K36: =H36-I36 -> 1701.215 | L36: =K36/H36 -> 0.20225556 | M36: B2C | N36: 46201 | O36: 46233 | P36: =N36+14 -> 46215 | Q36: 46204 | R36: =P36-Q36 -> 11 | S36: FALSE | T36: =IFS(S36=true,"แล้วเสร็จ",R36<1,"เลยกำหนด", R36>=1,"อยู่ในกำหนด") -> อยู่ในกำหนด | U36: CONSTRUCTION | V36: FALSE | W36: FALSE | X36: FALSE | Y36: FALSE | Z36: FALSE | AA36: FALSE | AC36: P'PANG
A37: ="Q" & INT((MATCH(B37, {"ม.ค.-26","ก.พ.-26","มี.ค.-26","เม.ย.-26","พ.ค.-26","มิ.ย.-26","ก.ค.-26","ส.ค.-26","ก.ย.-26","ต.ค.-26","พ.ย.-26","ธ.ค.-26"}, 0) + 2) / 3) -> Q3 | B37: =TEXT(O37, "mmm-yy") -> ก.ค.-26 | D37: ='Origin Plug & Play E22 Station'!B80 -> Origin Plug & Play E22 Station | E37: ='Origin Plug & Play E22 Station'!C80 -> Room 1628 | H37: ='Origin Plug & Play E22 Station'!I80 -> 140186.92 | I37: ='Origin Plug & Play E22 Station'!J80 -> 71605.756 | J37: ='Origin Plug & Play E22 Station'!M80 -> 67151.7 | K37: =H37-I37 -> 68581.16 | L37: =K37/H37 -> 0.48921227 | M37: B2C | N37: 46201 | O37: 46233 | P37: =N37+14 -> 46215 | Q37: 46204 | R37: =P37-Q37 -> 11 | S37: FALSE | T37: =IFS(S37=true,"แล้วเสร็จ",R37<1,"เลยกำหนด", R37>=1,"อยู่ในกำหนด") -> อยู่ในกำหนด | U37: CONSTRUCTION | V37: FALSE | W37: FALSE | X37: FALSE | Y37: FALSE | Z37: FALSE | AA37: FALSE | AC37: P'PANG
A38: ="Q" & INT((MATCH(B38, {"ม.ค.-26","ก.พ.-26","มี.ค.-26","เม.ย.-26","พ.ค.-26","มิ.ย.-26","ก.ค.-26","ส.ค.-26","ก.ย.-26","ต.ค.-26","พ.ย.-26","ธ.ค.-26"}, 0) + 2) / 3) -> Q3 | B38: =TEXT(O38, "mmm-yy") -> ก.ค.-26 | D38: ='Origin Plug & Play E22 Station'!B92 -> Origin Plug & Play E22 Station | E38: ='Origin Plug & Play E22 Station'!C92 -> Room 1628 | H38: ='Origin Plug & Play E22 Station'!I92 -> 32970 | I38: ='Origin Plug & Play E22 Station'!J92 -> 13000 | J38: ='Origin Plug & Play E22 Station'!M92 -> 13000 | K38: =H38-I38 -> 19970 | L38: =K38/H38 -> 0.60570215 | M38: B2C | N38: 46201 | O38: 46233 | P38: =N38+14 -> 46215 | Q38: 46204 | R38: =P38-Q38 -> 11 | S38: FALSE | T38: =IFS(S38=true,"แล้วเสร็จ",R38<1,"เลยกำหนด", R38>=1,"อยู่ในกำหนด") -> อยู่ในกำหนด | U38: CONSTRUCTION | V38: FALSE | W38: FALSE | X38: FALSE | Y38: FALSE | Z38: FALSE | AA38: FALSE | AC38: P'PANG
A39: ="Q" & INT((MATCH(B39, {"ม.ค.-26","ก.พ.-26","มี.ค.-26","เม.ย.-26","พ.ค.-26","มิ.ย.-26","ก.ค.-26","ส.ค.-26","ก.ย.-26","ต.ค.-26","พ.ย.-26","ธ.ค.-26"}, 0) + 2) / 3) -> Q3 | B39: =TEXT(O39, "mmm-yy") -> ก.ค.-26 | D39: ='Origin Plug & Play E22 Station'!B105 -> Origin Plug & Play E22 Station | E39: ='Origin Plug & Play E22 Station'!C105 -> Room 1628 | H39: ='Origin Plug & Play E22 Station'!I105 -> 8411.215 | I39: ='Origin Plug & Play E22 Station'!J105 -> 6710 | J39: ='Origin Plug & Play E22 Station'!M105 -> 6710 | K39: =H39-I39 -> 1701.215 | L39: =K39/H39 -> 0.20225556 | M39: B2C | N39: 46201 | O39: 46233 | P39: =N39+14 -> 46215 | Q39: 46204 | R39: =P39-Q39 -> 11 | S39: FALSE | T39: =IFS(S39=true,"แล้วเสร็จ",R39<1,"เลยกำหนด", R39>=1,"อยู่ในกำหนด") -> อยู่ในกำหนด | U39: CONSTRUCTION | V39: FALSE | W39: FALSE | X39: FALSE | Y39: FALSE | Z39: FALSE | AA39: FALSE | AC39: P'PANG
A40: ="Q" & INT((MATCH(B40, {"ม.ค.-26","ก.พ.-26","มี.ค.-26","เม.ย.-26","พ.ค.-26","มิ.ย.-26","ก.ค.-26","ส.ค.-26","ก.ย.-26","ต.ค.-26","พ.ย.-26","ธ.ค.-26"}, 0) + 2) / 3) -> Q3 | B40: =TEXT(O40, "mmm-yy") -> ก.ค.-26 | D40: ='Origin Plug & Play E22 Station'!B125 -> Origin Plug & Play E22 Station | E40: ='Origin Plug & Play E22 Station'!C125 -> Room 1629 | H40: ='Origin Plug & Play E22 Station'!I125 -> 93457.944 | I40: ='Origin Plug & Play E22 Station'!J125 -> 36162.7 | J40: ='Origin Plug & Play E22 Station'!M125 -> 37262.7 | K40: =H40-I40 -> 57295.244 | L40: =K40/H40 -> 0.61305911 | M40: B2C | N40: 46201 | O40: 46233 | P40: =N40+14 -> 46215 | Q40: 46204 | R40: =P40-Q40 -> 11 | S40: FALSE | T40: =IFS(S40=true,"แล้วเสร็จ",R40<1,"เลยกำหนด", R40>=1,"อยู่ในกำหนด") -> อยู่ในกำหนด | U40: CONSTRUCTION | V40: FALSE | W40: FALSE | X40: FALSE | Y40: FALSE | Z40: FALSE | AA40: FALSE | AC40: P'PANG
A41: ="Q" & INT((MATCH(B41, {"ม.ค.-26","ก.พ.-26","มี.ค.-26","เม.ย.-26","พ.ค.-26","มิ.ย.-26","ก.ค.-26","ส.ค.-26","ก.ย.-26","ต.ค.-26","พ.ย.-26","ธ.ค.-26"}, 0) + 2) / 3) -> Q3 | B41: =TEXT(O41, "mmm-yy") -> ก.ค.-26 | D41: ='Origin Plug & Play E22 Station'!B137 -> Origin Plug & Play E22 Station | E41: ='Origin Plug & Play E22 Station'!C137 -> Room 1629 | H41: ='Origin Plug & Play E22 Station'!I137 -> 54950 | I41: ='Origin Plug & Play E22 Station'!J137 -> 27000 | J41: ='Origin Plug & Play E22 Station'!M137 -> 27000 | K41: =H41-I41 -> 27950 | L41: =K41/H41 -> 0.50864422 | M41: B2C | N41: 46201 | O41: 46233 | P41: =N41+14 -> 46215 | Q41: 46204 | R41: =P41-Q41 -> 11 | S41: FALSE | T41: =IFS(S41=true,"แล้วเสร็จ",R41<1,"เลยกำหนด", R41>=1,"อยู่ในกำหนด") -> อยู่ในกำหนด | U41: CONSTRUCTION | V41: FALSE | W41: FALSE | X41: FALSE | Y41: FALSE | Z41: FALSE | AA41: FALSE | AC41: P'PANG
...

Sheet The Origin Sukhumvit-Praksa
J1: มูลค่าจัดจ้างซัพ | M1: Cost ประมาณการณ์
B2: โครงการ | C2: Room | D2: Area (sq.m.) | E2: SO | F2: PR | G2: PO | H2: รายการ สั่งซื้อ / สั่งจ้าง | I2: Revenue | J2: จัดจ้างจริง | K2: คงเหลือ (Exc. VAT บาท) | L2: % GP | M2: ประมาณการณ์ | N2: คงเหลือ (Exc. VAT บาท) | O2: % GP | P2: Status | Q2: วันที่ขออนุมัติ | R2: Suppiler
I3: (Ex.Vat) | J3: (Ex.Vat) | M3: (Ex.Vat) | P3: ขออนุัติครั้งนี้ / อนุมัติแล้ว
B4: The Origin Sukhumvit-Praksa | C4: Room 2514 | H4: 1. Curtain
E5: WAG-SONO23-000272 | F5: ORG-PRNO26-012942 | G5: WAG-PONO26-001561 | H5: 1.1 ผ้าม่านลอน ทึบ- จีบโปร่ง | I5: =11300/1.07 -> 10560.748 | J5: 4800 | K5: =I5-J5 -> 5760.7477 | L5: =K5/I5 -> 0.54548673 | M5: 4500 | N5: =I5-M5 -> 6060.7477 | O5: =N5/I5 -> 0.57389381 | P5: ขออนุมัติแล้ว | Q5: 46203 | R5: นาย วัฒน์ธรกรณ์ รุ่งพรทวีวัฒน์
H6: 1.2 ผ้าม่านม้วน | I6: =5400/1.07 -> 5046.729 | J6: 2200 | K6: =I6-J6 -> 2846.729 | L6: =K6/I6 -> 0.56407407 | M6: 1800 | N6: =I6-M6 -> 3246.729 | O6: =N6/I6 -> 0.64333333
H7: 1.3 งานติดตั้ง | I7: 0 | J7: 1500 | K7: =I7-J7 -> -1500 | L7: =K7/I7 -> #DIV/0! | M7: 1500 | N7: =I7-M7 -> -1500 | O7: =N7/I7 -> #DIV/0!
H8: ส่วนลด | I8: =-3340/1.07 -> -3121.4953 | J8: -500
I9: =-3000/1.07 -> -2803.7383
I10: =-360/1.07 -> -336.4486
B19: =B4 -> The Origin Sukhumvit-Praksa | C19: =C4 -> Room 2514 | D19: =SUM(D4:D18) -> 0 | H19: TOTAL | I19: =SUM(I5:I17) -> 9345.7944 | J19: =SUM(J4:J18) -> 8000 | K19: =I19-J19 -> 1345.7944 | L19: =K19/I19 -> 0.144 | M19: =SUM(M4:M18) -> 7800 | N19: =I19-M19 -> 1545.7944 | O19: =N19/I19 -> 0.1654

Sheet Origin Plug & Play Sirindhorn S
J1: มูลค่าจัดจ้างซัพ | M1: Cost ประมาณการณ์
B2: โครงการ | C2: Room | D2: Area (sq.m.) | E2: SO | F2: PR | G2: PO | H2: รายการ สั่งซื้อ / สั่งจ้าง | I2: Revenue | J2: จัดจ้างจริง | K2: คงเหลือ (Exc. VAT บาท) | L2: % GP | M2: ประมาณการณ์ | N2: คงเหลือ (Exc. VAT บาท) | O2: % GP | P2: Status | Q2: วันที่ขออนุมัติ | R2: Suppiler
I3: (Ex.Vat) | J3: (Ex.Vat) | M3: (Ex.Vat) | P3: ขออนุัติครั้งนี้ / อนุมัติแล้ว
B4: Origin Plug & Play Sirindhorn Station | C4: Room B1009 | E4: WAG-SONO26-000536 | F4: ORG-PRNO26-015215 | G4: WAG-PONO26-001659 | H4: 1. Built in
H5: 1.1 ตู้เหนือตู้เย็น | I5: =16600/1.07 -> 15514.019 | J5: =6500*1.1 -> 7150 | K5: =I5-J5 -> 8364.0187 | L5: =K5/I5 -> 0.53912651 | M5: 10000 | N5: =I5-M5 -> 5514.0187 | O5: =N5/I5 -> 0.35542169 | P5: ขออนุมัติแล้ว | Q5: 46232 | R5: บริษัท ดีดี อินทีเรีย จำกัด
H6: 1.2 ชุดบิ้วท์ตู้ทีวี : ตู้สูง + ตู้วางทีวีมีลิ้นชัก + ไม้ระแนงกรุผนัง + ชั้นวางติดผนังเหนือทีวี | I6: =69800/1.07 -> 65233.645 | J6: =32000*1.1 -> 35200 | K6: =I6-J6 -> 30033.645 | L6: =K6/I6 -> 0.46040115 | M6: 42000 | N6: =I6-M6 -> 23233.645 | O6: =N6/I6 -> 0.35616046
H7: 1.3 ชั้นวางติดผนังสามชั้น + เบิ้นผนังซอกหลังเตียง และหัวเตียง มุมโค้ง | I7: =28500/1.07 -> 26635.514 | J7: =16000*1.1 -> 17600 | K7: =I7-J7 -> 9035.514 | L7: =K7/I7 -> 0.33922807 | M7: 19000 | N7: =I7-M7 -> 7635.514 | O7: =N7/I7 -> 0.28666667
H8: 1.4 ชั้นวางติดผนังสามชั้น + เบิ้นผนังซอกหลังโซฟา กรุไม้ระแนง | I8: =23900/1.07 -> 22336.449 | J8: =15000*1.1 -> 16500 | K8: =I8-J8 -> 5836.4486 | L8: =K8/I8 -> 0.26129707 | M8: 17000 | N8: =I8-M8 -> 5336.4486 | O8: =N8/I8 -> 0.23891213
H9: 1.5 ลิ้นชักเครื่องประดับ : แผ่นบนกระจกใส + แผ่นถาดเครื่องประดับ + ช่องลิ้นชัก | I9: =12400/1.07 -> 11588.785 | J9: =15000*1.1 -> 16500 | K9: =I9-J9 -> -4911.215 | L9: =K9/I9 -> -0.42379032 | M9: 8000 | N9: =I9-M9 -> 3588.785 | O9: =N9/I9 -> 0.30967742
H10: ส่วนลด | I10: =-3200/1.07 -> -2990.6542 | J10: -2295.79 | K10: 0 | L10: 0 | M10: 0 | N10: 0 | O10: 0
B11: =B4 -> Origin Plug & Play Sirindhorn Station | C11: =C4 -> Room B1009 | D11: =SUM(D4:D10) -> 0 | H11: TOTAL | I11: =SUM(I5:I10) -> 138317.76 | J11: =SUM(J4:J10) -> 90654.21 | K11: =I11-J11 -> 47663.547 | L11: =K11/I11 -> 0.34459456 | M11: =SUM(M4:M10) -> 96000 | N11: =I11-M11 -> 42317.757 | O11: =N11/I11 -> 0.30594595
B13: Origin Plug & Play Sirindhorn Station | C13: Room C1209 | H13: 1. Curtain
H14: 1.1 ชุดหน้าต่างห้องนอนชั้นบน ผ้าม่านทึบ+ม่านโปร่ง | I14: =12000/1.07 -> 11214.953 | K14: =I14-J14 -> 11214.953 | L14: =K14/I14 -> 1 | M14: 7500 | N14: =I14-M14 -> 3714.9533 | O14: =N14/I14 -> 0.33125 | P14: ขออนุมัติแล้ว | Q14: 46245
H15: ส่วนลด | I15: =-1000/1.07 -> -934.57944 | K15: 0 | L15: 0 | M15: 0 | N15: 0 | O15: 0
B16: =B13 -> Origin Plug & Play Sirindhorn Station | C16: =C13 -> Room C1209 | D16: =SUM(D13:D15) -> 0 | H16: TOTAL | I16: =SUM(I14:I15) -> 10280.374 | J16: =SUM(J13:J15) -> 0 | K16: =I16-J16 -> 10280.374 | L16: =K16/I16 -> 1 | M16: =SUM(M13:M15) -> 7500 | N16: =I16-M16 -> 2780.3738 | O16: =N16/I16 -> 0.27045455

Sheet Origin Place Bangna
B1: โครงการ | C1: Room | H1: รายการ สั่งซื้อ / สั่งจ้าง | I1: Revenue | J1: มูลค่าจัดจ้างซัพ | M1: Cost ประมาณการณ์ | P1: Status | Q1: วันที่ขออนุมัติ | R1: Suppiler
D2: Area (sq.m.) | E2: SO | F2: PR | G2: PO | J2: จัดจ้างจริง | K2: คงเหลือ (Exc. VAT บาท) | L2: % GP | M2: ประมาณการณ์ | N2: คงเหลือ (Exc. VAT บาท) | O2: % GP
I3: (Ex.Vat) | J3: (Ex.Vat) | M3: (Ex.Vat) | P3: ขออนุัติครั้งนี้ / อนุมัติแล้ว
B4: Origin Place Bangna | C4: Room 532 | D4: 1BEDPLUS | E4: WAG-SONO26-000345 | F4: ORG-PRNO26-014769 | H4: 1. Curtain
H5: 1.1 ผ้าม่านห้องนอนใหญ่ | I5: =47000/1.07 -> 43925.234 | M5: 28000 | N5: =I5-M5 -> 15925.234 | O5: =N5/I5 -> 0.36255319 | P5: ขออนุมัติแล้ว | Q5: 46195
H6: 1.2 ผ้าม่านห้องนอนเล็ก
H7: 1.3 ผ้าม่านห้องนั่งเล่น (หน้าต่าง)
H8: 1.4 ผ้าม่านห้องนั่งเล่น (ระเบียง)
H9: 1.3 งานติดตั้ง
G10: WAG-PONO26-001644 | H10: 2. Built in | R10: บริษัท ดีดี อินทีเรีย จำกัด
H11: 2.1 ต่อเติมช่องครัวเป็นตู้บานปิด มีชั้นปรับภายใน | I11: =18000/1.07 -> 16822.43 | J11: 5900 | K11: =I11-J11 -> 10922.43 | L11: =K11/I11 -> 0.64927778 | M11: 10000 | N11: =I11-M11 -> 6822.4299 | O11: =N11/I11 -> 0.40555556
H12: 2.2 ต่อเติมตู้เหนือตู้เย็น ตู้บานเปิดคู่ | I12: =16000/1.07 -> 14953.271 | J12: 6000 | K12: =I12-J12 -> 8953.271 | L12: =K12/I12 -> 0.59875 | M12: 10000 | N12: =I12-M12 -> 4953.271 | O12: =N12/I12 -> 0.33125
H13: 2.3 ตู้ทีวี + ผนังระแนงไม้หลังทีวี ชั้นวางติดผนังเหนือทีวี + เดินสายไฟทำปลั๊กไฟเพิ่มหลังทีวี | I13: =43200/1.07 -> 40373.832 | J13: 29500 | K13: =I13-J13 -> 10873.832 | L13: =K13/I13 -> 0.2693287 | M13: 28000 | N13: =I13-M13 -> 12373.832 | O13: =N13/I13 -> 0.30648148
H14: 2.4 เตียงบิ้วท์อิน 3.5 ฟุต / เว้นใต้เตียง ไว้ใส่เตียงเลื่อน | I14: =24200/1.07 -> 22616.822 | J14: 9500 | K14: =I14-J14 -> 13116.822 | L14: =K14/I14 -> 0.57995868 | M14: 15000 | N14: =I14-M14 -> 7616.8224 | O14: =N14/I14 -> 0.33677686
H15: 2.5 หัวเตียงห้องนอนใหญ่ เบิ้น 10 ซม. เดินสายไฟทำปลั๊ก 2 ข้าง / ทำชั้นวางของซอกเสา / ผนังเหนือหัวเตียงกรุลามิเนตลายผ้าสีเทา | I15: =38400/1.07 -> 35887.85 | J15: 20000 | K15: =I15-J15 -> 15887.85 | L15: =K15/I15 -> 0.44270833 | M15: 30000 | N15: =I15-M15 -> 5887.8505 | O15: =N15/I15 -> 0.1640625
H16: 2.6 กรุกระเบื้องผนังครัว | I16: =9000/1.07 -> 8411.215 | J16: 8500 | K16: =I16-J16 -> -88.785047 | L16: =K16/I16 -> -0.010555556 | M16: 5500 | N16: =I16-M16 -> 2911.215 | O16: =N16/I16 -> 0.34611111
H17: 2.7 เดินท่อสำหรับท่อน้ำแอร์ | I17: =3100/1.07 -> 2897.1963 | J17: 1500 | K17: =I17-J17 -> 1397.1963 | L17: =K17/I17 -> 0.48225806 | M17: 2000 | N17: =I17-M17 -> 897.19626 | O17: =N17/I17 -> 0.30967742
H18: 2.8 ค่าดำเนินการ | I18: 0 | J18: 3756.08 | K18: =I18-J18 -> -3756.08 | L18: =K18/I18 -> #DIV/0! | M18: =sum(M11:M17)*10% -> 10050 | N18: =I18-M18 -> -10050 | O18: =N18/I18 -> #DIV/0!
B21: =B4 -> Origin Place Bangna | C21: =C4 -> Room 532 | D21: =SUM(D4:D20) -> 0 | H21: TOTAL | I21: =SUM(I5:I19) -> 185887.85 | J21: =SUM(J4:J20) -> 84656.08 | K21: =I21-J21 -> 101231.77 | L21: =K21/I21 -> 0.54458519 | M21: =SUM(M4:M20) -> 138550 | N21: =I21-M21 -> 47337.85 | O21: =N21/I21 -> 0.25465812

Sheet Origin Play Bangkhunnon
B1: โครงการ | C1: Room | D1: Area (sq.m.) | H1: รายการ สั่งซื้อ / สั่งจ้าง | I1: Revenue | J1: มูลค่าจัดจ้างซัพ | M1: Cost ประมาณการณ์ | P1: Status | Q1: วันที่ขออนุมัติ
E2: SO | F2: PR | G2: PO | J2: จัดจ้างจริง | K2: คงเหลือ (Exc. VAT บาท) | L2: % GP | M2: ประมาณการณ์ | N2: คงเหลือ (Exc. VAT บาท) | O2: % GP | R2: Suppiler
I3: (Ex.Vat) | J3: (Ex.Vat) | M3: (Ex.Vat) | P3: ขออนุัติครั้งนี้ / อนุมัติแล้ว
B4: Origin Play Bangkhunnon | C4: Room 1809 | I4: =SUM(I5:I18) -> 26000 | J4: =SUM(J5:J18) -> 14000 | K4: =SUM(K6:K18) -> 12000 | L4: =K4/I4 -> 0.46153846 | M4: =SUM(M5:M18) -> 17000 | N4: =I4-M4 -> 9000 | O4: =N4/I4 -> 0.34615385
H6: 1. Curtain
E7: WAG-SONO25-000922 | F7: ORG-PRNO26-012939 | G7: WAG-PONO26-001560 | H7: 1.1 ทึบ-โปร่ง ชั้นล่าง | I7: =26000 -> 26000 | J7: 14000 | K7: =I7-J7 -> 12000 | L7: =K7/I7 -> 0.46153846 | M7: 17000 | N7: =I7-M7 -> 9000 | O7: =N7/I7 -> 0.34615385 | P7: ขออนุมัติแล้ว | Q7: 46203 | R7: นาย วัฒน์ธรกรณ์ รุ่งพรทวีวัฒน์
B19: =B4 -> Origin Play Bangkhunnon | C19: =C4 -> Room 1809 | D19: =SUM(D4:D18) -> 0 | H19: TOTAL | I19: =SUM(I6:I18) -> 26000 | J19: =SUM(J6:J18) -> 14000 | K19: =SUM(K6:K18) -> 12000 | L19: =K19/I19 -> 0.46153846 | M19: =SUM(M6:M18) -> 17000 | N19: =I19-M19 -> 9000 | O19: =N19/I19 -> 0.34615385
B21: Origin Play Bangkhunnon | C21: Room 901 | H21: 1. Curtain
E22: WAG-SONO25-000833 | F22: ORG-PRNO26-012592 | G22: WAG-PONO26-001586 | H22: ผ้าม่านจีบ ทึบ-โปร่ง ห้องนอน | I22: =14200/1.07 -> 13271.028 | J22: 5500 | K22: =I22-J22 -> 7771.028 | L22: =K22/I22 -> 0.58556338 | P22: ขออนุมัติแล้ว | Q22: 46199 | R22: นาย วัฒน์ธรกรณ์ รุ่งพรทวีวัฒน์
H23: ผ้าม่านจีบ ทึบ-โปร่ง ห้องนั่งเล่น | I23: =14200/1.07 -> 13271.028 | J23: 5200 | K23: =I23-J23 -> 8071.028 | L23: =K23/I23 -> 0.60816901
H24: มู่ลี่ไม้ | I24: =12200/1.07 -> 11401.869 | J24: 4800 | K24: =I24-J24 -> 6601.8692 | L24: =K24/I24 -> 0.57901639
H25: ค่าแรง-ติดตั้ง | I25: 0 | J25: 1500 | K25: =I25-J25 -> -1500 | L25: =K25/I25 -> #DIV/0!
H26: 2. Wallpaper
G27: WAG-PONO26-001587 | H27: วอลเปเปอร์ รอบห้อง สีพื้น 1 สี | I27: =27800/1.07 -> 25981.308 | J27: 7125 | K27: =I27-J27 -> 18856.308 | L27: =K27/I27 -> 0.72576439 | R27: บริษัท สิริ เดคคอร์ อินเตอร์เนชั่นแนล จำกัด
G28: WAG-PONO26-001588 | H28: ค่าแรง-ติดตั้ง | I28: 0 | J28: 3800 | K28: =I28-J28 -> -3800 | L28: =K28/I28 -> #DIV/0! | R28: บริษัท มิสเตอร์ เดคคอร์ จำกัด
H29: 3. Built in
G30: WAG-PONO26-001497 | H30: ตู้สูงเก็บของ L shape โครงไม้ปิดผิว Laminate ลายไม้ หน้าบานกระจกใสธรรมดา เฟรมอลูมิเนียมสีดำ มือจับโปรไฟล์ 6 บาน ด้านล่างทำหน้าบานทึบ ปิดผิว Laminate ลายไม้ 6 บาน ภายในทำชั้นปรับระดับ พร้อมอุปกรณ์ Soft Close | I30: =159400/1.07 -> 148971.96 | J30: 86915.88 | K30: =I30-J30 -> 62056.083 | L30: =K30/I30 -> 0.41656216 | R30: บริษัท ล้านเจริญ เฟอร์นิเจอร์ จำกัด
H31: ส่วนลด | I31: =-45560/1.07 -> -42579.439
I32: =-3000/1.07 -> -2803.7383
B34: =B21 -> Origin Play Bangkhunnon | C34: =C21 -> Room 901 | D34: =SUM(D21:D33) -> 0 | H34: TOTAL | I34: =SUM(I21:I33) -> 167514.02 | J34: =SUM(J21:J33) -> 114840.88 | K34: =I34-J34 -> 52673.139 | L34: =K34/I34 -> 0.31444018 | M34: =SUM(M21:M33) -> 0 | N34: =I34-M34 -> 167514.02 | O34: =N34/I34 -> 1
B36: Origin Play Bangkhunnon | C36: Room 2324 | H36: 1. Loose Furniture
E37: WAG-SONO25-000825 | F37: ORG-PRNO26-014517 | G37: WAG-PONO26-001599 | H37: โต๊ะกลาง | I37: =2000/1.07 -> 1869.1589 | J37: 1178.88 | K37: =I37-J37 -> 690.27888 | L37: =K37/I37 -> 0.3692992 | M37: 1166 | N37: =I37-M37 -> 703.15888 | O37: =N37/I37 -> 0.37619 | P37: ขออนุมัติแล้ว | Q37: 46223 | R37: บริษัท ชิค รีพับบลิค จำกัด (มหาชน)
H38: 2. Electrical Appliance
G39: WAG-PONO26-001600 | H39: เครื่องทำน้ำอุ่น | I39: =3500/1.07 -> 3271.028 | J39: 2200 | K39: =I39-J39 -> 1071.028 | L39: =K39/I39 -> 0.32742857 | M39: 2200 | N39: =I39-M39 -> 1071.028 | O39: =N39/I39 -> 0.32742857 | R39: บริษัท อีเลคโทรลักซ์ ประเทศไทย จำกัด
B41: =B36 -> Origin Play Bangkhunnon | C41: =C36 -> Room 2324 | D41: =SUM(D36:D40) -> 0 | H41: TOTAL | I41: =SUM(I36:I40) -> 5140.1869 | J41: =SUM(J36:J40) -> 3378.88 | K41: =I41-J41 -> 1761.3069 | L41: =K41/I41 -> 0.34265425 | M41: =SUM(M36:M40) -> 3366 | N41: =I41-M41 -> 1774.1869 | O41: =N41/I41 -> 0.34516
B43: Origin Play Bangkhunnon | C43: Room 1121 | E43: WAG-SONO25-000876 | F43: ORG-PRNO26-014519 | H43: 1. Curtain
H44: ห้องนั่งเล่น ผ้าม่าน ลอนทึบ ม่านจีบโปร่ง | I44: =13500/1.07 -> 12616.822 | M44: 5750 | N44: =I44-M44 -> 6866.8224 | O44: =N44/I44 -> 0.54425926 | P44: ขออนุมัติแล้ว | Q44: 46223 | R44: นาย วัฒน์ธรกรณ์ รุ่งพรทวีวัฒน์
H45: ห้องนอนใหญ่ ผ้าม่าน ลอนทึบ ม่านจีบโปร่ง | I45: =12200/1.07 -> 11401.869 | M45: 5175 | N45: =I45-M45 -> 6226.8692 | O45: =N45/I45 -> 0.54612705
H46: ห้องทำงาน ผ้าม่าน ลอนทึบ ม่านจีบโปร่ง | I46: =12200/1.07 -> 11401.869 | M46: 5175 | N46: =I46-M46 -> 6226.8692 | O46: =N46/I46 -> 0.54612705
H47: ค่าแรง-ติดตั้ง | I47: 0 | M47: 1500 | N47: =I47-M47 -> -1500 | O47: =N47/I47 -> #DIV/0!
G48: WAG-PONO26-001613 | H48: 3. Built in | R48: บริษัท เอสไอ เดคคอเรท จำกัด สำนักงานใหญ่
H49: ตู้หนังสือหลังโซฟา ตู้วางหนังสือไม่มีหน้าบาน+ชั้นวางของ | I49: =48000/1.07 -> 44859.813 | J49: 25000 | K49: =I49-J49 -> 19859.813 | L49: =K49/I49 -> 0.44270833 | M49: 31240 | N49: =I49-M49 -> 13619.813 | O49: =N49/I49 -> 0.30360833
H50: ตู้หนังสือห้องทำงาน ตู้วางหนังสือไม่มีหน้าบาน+ ตู้เก็บของบานเปิดปิด ด้านล่างปิดผิวลามิเนต มีกุญแจล็อค | I50: =64500/1.07 -> 60280.374 | J50: 35350 | K50: =I50-J50 -> 24930.374 | L50: =K50/I50 -> 0.41357364 | M50: 36121.25 | N50: =I50-M50 -> 24159.124 | O50: =N50/I50 -> 0.40077926
H51: ส่วนลด | I51: =-30080/1.07 -> -28112.15
I52: =-3000/1.07 -> -2803.7383
B53: =B43 -> Origin Play Bangkhunnon | C53: =C43 -> Room 1121 | D53: =SUM(D43:D52) -> 0 | H53: TOTAL | I53: =SUM(I43:I52) -> 109644.86 | J53: =SUM(J43:J52) -> 60350 | K53: =I53-J53 -> 49294.86 | L53: =K53/I53 -> 0.4495866 | M53: =SUM(M43:M52) -> 84961.25 | N53: =I53-M53 -> 24683.61 | O53: =N53/I53 -> 0.22512327
B55: Origin Play Bangkhunnon | C55: Room 1621
H57: 1. Curtain
E58: WAG-SONO25-000795 | F58: ORG-PRNO26-013246 | G58: WAG-PONO26-001617 | H58: 1.1 ม่าน ทึบลอนโปร่งจีบ | I58: =24680/1.07 -> 23065.421 | J58: 15000 | K58: =I58-J58 -> 8065.4206 | L58: =K58/I58 -> 0.34967585 | M58: 16000 | N58: =I58-M58 -> 7065.4206 | O58: =N58/I58 -> 0.30632091 | P58: ขออนุมัติแล้ว | Q58: 46209 | R58: นาย วัฒน์ธรกรณ์ รุ่งพรทวีวัฒน์
B70: =B55 -> Origin Play Bangkhunnon | C70: =C55 -> Room 1621 | D70: =SUM(D55:D69) -> 0 | H70: TOTAL | I70: =SUM(I57:I69) -> 23065.421 | J70: =SUM(J57:J69) -> 15000 | K70: =SUM(K57:K69) -> 8065.4206 | L70: =K70/I70 -> 0.34967585 | M70: =SUM(M57:M69) -> 16000 | N70: =I70-M70 -> 7065.4206 | O70: =N70/I70 -> 0.30632091
...

Sheet Origin Place Phetkasem
A1: / | J1: มูลค่าจัดจ้างซัพ | M1: Cost ประมาณการณ์
B2: โครงการ | C2: Room | D2: Area (sq.m.) | E2: SO | F2: PR | G2: PO | H2: รายการ สั่งซื้อ / สั่งจ้าง | I2: Revenue | J2: จัดจ้างจริง | K2: คงเหลือ (Exc. VAT บาท) | L2: % GP | M2: ประมาณการณ์ | N2: คงเหลือ (Exc. VAT บาท) | O2: % GP | P2: Status | Q2: วันที่ขออนุมัติ | R2: Suppiler
I3: (Ex.Vat) | J3: (Ex.Vat) | M3: (Ex.Vat) | P3: ขออนุัติครั้งนี้ / อนุมัติแล้ว
B4: Origin Place Phetkasem | C4: Room 919 | H4: 1. Curtain
E5: WAG-SONO26-000443 | F5: ORG-PRNO26-014468 | G5: WAG-PONO26-001595 | H5: 1.1 ผ้าม่านจีบ ทึบ ห้องนั่งเล่น (หน้าต่าง) | I5: =11900/1.07 -> 11121.495 | J5: 5500 | K5: =sum(I5:I6)-J5 -> 12350.467 | L5: =K5/SUM(I5:I6) -> 0.69188482 | M5: 4000 | N5: =I5-M5 -> 7121.4953 | O5: =N5/I5 -> 0.64033613 | P5: ขออนุมัติแล้ว | Q5: 46220 | R5: นาย วัฒน์ธรกรณ์ รุ่งพรทวีวัฒน์
H6: 1.2 ผ้าม่านจีบ โปร่ง ห้องนั่งเล่น (หน้าต่าง) | I6: =7200/1.07 -> 6728.972 | M6: 2500 | N6: =I6-M6 -> 4228.972 | O6: =N6/I6 -> 0.62847222
H7: 1.3 ผ้าม่านจีบ ทึบ ห้องนั่งเล่น (ระเบียง) | I7: =6000/1.07 -> 5607.4766 | J7: 5200 | K7: =sum(I7:I8)-J7 -> 3771.9626 | L7: =K7/SUM(I7:I8) -> 0.42041667 | M7: 2500 | N7: =I7-M7 -> 3107.4766 | O7: =N7/I7 -> 0.55416667
H8: 1.4 ผ้าม่านจีบ โปร่ง ห้องนั่งเล่น (ระเบียง) | I8: =3600/1.07 -> 3364.486 | M8: 1500 | N8: =I8-M8 -> 1864.486 | O8: =N8/I8 -> 0.55416667
H9: 1.5 ผ้าม่านจีบ ทึบ ชั้นลอย | I9: =15000/1.07 -> 14018.692 | J9: 5000 | K9: =I9-J9 -> 9018.6916 | L9: =K9/I9 -> 0.64333333 | M9: 8000 | N9: =I9-M9 -> 6018.6916 | O9: =N9/I9 -> 0.42933333
H10: 1.6 ค่าแรง-ติดตั้ง | I10: 0 | J10: 2500 | K10: =I10-J10 -> -2500 | L10: =K10/I10 -> #DIV/0! | M10: 4000 | N10: =I10-M10 -> -4000 | O10: =N10/I10 -> #DIV/0!
J11: -200
H12: 2. Wallpaper
G13: WAG-PONO26-001596 | H13: 2.1 วอลเปเปอร์ รอบห้อง สีพื้น 1 สี | I13: =28300/1.07 -> 26448.598 | J13: 9975 | K13: =I13-J13 -> 16473.598 | L13: =K13/I13 -> 0.62285336 | M13: 15000 | N13: =I13-M13 -> 11448.598 | O13: =N13/I13 -> 0.43286219 | R13: บริษัท สิริ เดคคอร์ อินเตอร์เนชั่นแนล จำกัด
G14: WAG-PONO26-001597 | H14: 2.2 ค่าแรง-ติดตั้ง | I14: 0 | J14: 4200 | K14: =I14-J14 -> -4200 | L14: =K14/I14 -> #DIV/0! | M14: 0 | N14: =I14-M14 -> 0 | O14: =N14/I14 -> #DIV/0! | R14: บริษัท มิสเตอร์ เดคคอร์ จำกัด
I15: =-14400/1.07 -> -13457.944
I16: =-3000/1.07 -> -2803.7383
B21: =B4 -> Origin Place Phetkasem | C21: =C4 -> Room 919 | D21: =SUM(D4:D20) -> 0 | H21: TOTAL | I21: =SUM(I4:I20) -> 51028.037 | J21: =SUM(J4:J20) -> 32175 | K21: =I21-J21 -> 18853.037 | L21: =K21/I21 -> 0.36946429 | M21: =SUM(M4:M20) -> 37500 | N21: =I21-M21 -> 13528.037 | O21: =N21/I21 -> 0.26510989
B23: Origin Place Phetkasem | C23: Room 818 | D23: 25 sqm. | H23: 1. Curtain
D24: 1Bed Smart Kitchen | E24: WAG-SONO26-000588 | F24: ORG-PRNO26-014490 | G24: WAG-PONO26-001592 | H24: ผ้าม่านจีบ ทึบ (หน้าต่าง) | I24: =7200/1.07 -> 6728.972 | J24: 3000 | K24: =I24-J24 -> 3728.972 | L24: =K24/I24 -> 0.55416667 | M24: 3000 | N24: =I24-M24 -> 3728.972 | O24: =N24/I24 -> 0.55416667 | P24: ขออนุมัติแล้ว | Q24: 46220 | R24: นาย วัฒน์ธรกรณ์ รุ่งพรทวีวัฒน์
H25: ผ้าม่านจีบ โปร่ง (หน้าต่าง) | I25: =4300/1.07 -> 4018.6916 | J25: 1800 | K25: =I25-J25 -> 2218.6916 | L25: =K25/I25 -> 0.55209302 | M25: 1800 | N25: =I25-M25 -> 2218.6916 | O25: =N25/I25 -> 0.55209302
H26: ผ้าม่านจีบ ทึบ (กั้นห้อง) | I26: =5300/1.07 -> 4953.271 | J26: 2000 | K26: =I26-J26 -> 2953.271 | L26: =K26/I26 -> 0.59622642 | M26: 2200 | N26: =I26-M26 -> 2753.271 | O26: =N26/I26 -> 0.55584906
H27: ติดตั้ง | I27: 0 | J27: 1500 | K27: =I27-J27 -> -1500 | L27: =K27/I27 -> #DIV/0! | M27: 1500 | N27: =I27-M27 -> -1500 | O27: =N27/I27 -> #DIV/0!
J28: -300
H29: 2. Wallpaper
G30: WAG-PONO26-001593 | H30: 2.1 วอลเปเปอร์ รอบห้อง สีพื้น 1 สี | I30: =19400/1.07 -> 18130.841 | J30: 6175 | K30: =I30-J30 -> 11955.841 | L30: =K30/I30 -> 0.6594201 | M30: 8125 | N30: =I30-M30 -> 10005.841 | O30: =N30/I30 -> 0.55186856 | R30: บริษัท สิริ เดคคอร์ อินเตอร์เนชั่นแนล จำกัด
G31: WAG-PONO26-001594 | H31: 2.2 ค่าแรง-ติดตั้ง | I31: 0 | J31: 2600 | K31: =I31-J31 -> -2600 | L31: =K31/I31 -> #DIV/0! | M31: 3400 | N31: =I31-M31 -> -3400 | O31: =N31/I31 -> #DIV/0! | R31: บริษัท มิสเตอร์ เดคคอร์ จำกัด
H32: ส่วนลด | I32: =-3620/1.07 -> -3383.1776
I33: =-3000/1.07 -> -2803.7383
B38: =B23 -> Origin Place Phetkasem | C38: =C23 -> Room 818 | D38: =SUM(D23:D37) -> 0 | H38: TOTAL | I38: =SUM(I23:I37) -> 27644.86 | J38: =SUM(J23:J37) -> 16775 | K38: =I38-J38 -> 10869.86 | L38: =K38/I38 -> 0.39319642 | M38: =SUM(M23:M37) -> 20025 | N38: =I38-M38 -> 7619.8598 | O38: =N38/I38 -> 0.27563387
B40: Origin Place Phetkasem | C40: Room 502 | H40: 1. Built in
H41: 1.1 Built in | I41: =486200/1.07 -> 454392.52 | J41: =246450-3000 -> 243450 | M41: =295050/1.07 -> 275747.66 | N41: =I41-M41 -> 178644.86 | O41: =N41/I41 -> 0.39315097 | P41: ขออนุมัติแล้ว | Q41: 46252
H42: 1.2 ระบบติดตั้งม่านไฟฟ้า | I42: =20000/1.07 -> 18691.589 | J42: 3000 | M42: =14000/1.07 -> 13084.112 | N42: =I42-M42 -> 5607.4766 | O42: =N42/I42 -> 0.3
H43: 2. Curtain
H44: 2.1 ผ้าม่านม้วน ห้องนั่งเล่น (หน้าต่าง) | I44: =18000/1.07 -> 16822.43 | M44: =8000/1.07 -> 7476.6355 | N44: =I44-M44 -> 9345.7944 | O44: =N44/I44 -> 0.55555556
H45: 2.2 ผ้าม่านม้วน ห้องนั่งเล่น (ระเบียง) | I45: =9600/1.07 -> 8971.9626 | M45: =4000/1.07 -> 3738.3178 | N45: =I45-M45 -> 5233.6449 | O45: =N45/I45 -> 0.58333333
H46: 2.3 ค่าแรง-ติดตั้ง ผ้าม่าน | I46: 0 | M46: =3000/1.07 -> 2803.7383 | N46: =I46-M46 -> -2803.7383 | O46: =N46/I46 -> #DIV/0!
H47: 3. Wallpaper
H48: 3.1 Wallpaper | I48: =28300/1.07 -> 26448.598 | M48: =11875/1.07 -> 11098.131 | N48: =I48-M48 -> 15350.467 | O48: =N48/I48 -> 0.58038869
H49: 3.2 ค่าแรงติดตั้ง Wallpaper | I49: 0 | M49: =5950/1.07 -> 5560.7477 | N49: =I49-M49 -> -5560.7477 | O49: =N49/I49 -> #DIV/0!
H50: 4. Film
...

Sheet IP Program Origin Place Bangna
K1: มูลค่าจัดจ้างซัพ | N1: Cost ประมาณการณ์
B2: โครงการ | C2: Room | D2: Area (sq.m.) | E2: Suppiler | F2: SO | G2: PR | H2: PO | I2: รายการ สั่งซื้อ / สั่งจ้าง | J2: Revenue | K2: จัดจ้างจริง | L2: คงเหลือ (Exc. VAT บาท) | M2: % GP | N2: ประมาณการณ์ | O2: คงเหลือ (Exc. VAT บาท) | P2: % GP | Q2: Status | R2: วันที่ขออนุมัติ
J3: (Ex.Vat) | K3: (Ex.Vat) | N3: (Ex.Vat) | Q3: ขออนุัติครั้งนี้ / อนุมัติแล้ว
B4: Origin Place Bangna | C4: IP Program | F4: WAG-SONO25-000873 | I4: 1. Decorate Prop
B5: 1. OBB-CTNO25-00108 | E5: บริษัท เมมโมรี่ส์ ดีไซน์ แอนด์ พริ้นท์ จำกัด | G5: ORG-PRNO25-031604 | H5: WAG-PONO25-002535 | I5: 1.1 กรอบรูป | K5: 45000
B6: 2. OBB-CTNO25-00107 | E6: นางสาว อังค์วรา ฉันท์ฉกาจสิริ | H6: WAG-PONO26-000037 | I6: 1.2 หมอนอิง | K6: 81378.9
B7: 3. OBB-CTNO25-00109 | E7: บริษัท เพื่อภูมิ จำกัด | H7: WAG-PONO26-000038 | I7: 1.3 โคมไฟ | K7: 89100
E8: บริษัท เจ็ง กีสข่าน จำกัด | G8: ORG-PRNO25-032195 | H8: WAG-PONO26-000137 | I8: 1.4 งานจัดพร็อพ | K8: 42400
E9: ณีรนุช โกทันย์ | G9: ORG-PRNO26-004625 | H9: WAG-PONO26-000698 | I9: 1.5 งานจัดวางของเข้าห้อง | K9: 75000
E10: บริษัท อิคาโน่ (ประเทศไทย) จำกัด | G10: ORG-PRNO26-008086 | H10: WAG-PONO26-000949 | I10: 1.6 พร็อพ IKEA | K10: 173652
E11: บริษัท เอ็ม-เวิลด์ โลจิสติกส์ (ประเทศไทย) จำกัด | H11: WAG-PONO26-000950 | I11: 1.7 ขนส่งพร็อพ IKEA | K11: 5500
E12: บริษัท เมมโมรี่ส์ ดีไซน์ แอนด์ พริ้นท์ จำกัด | G12: ORG-PRNO26-014551 | H12: WAG-PONO26-001608 | I12: 1.8 กรอบรูป | K12: 10350
E13: บริษัท อิคาโน่ (ประเทศไทย) จำกัด | G13: ORG-PRNO26-014599 | H13: WAG-PONO26-001611 | I13: 1.9 โคมไฟ IKEA | K13: 14390
E14: บริษัท เอ็ม-เวิลด์ โลจิสติกส์ (ประเทศไทย) จำกัด | H14: WAG-PONO26-001612 | I14: 1.10 ขนส่ง โคมไฟ IKEA | K14: 290
E15: บริษัท เมมโมรี่ส์ ดีไซน์ แอนด์ พริ้นท์ จำกัด | G15: ORG-PRNO26-015359 | H15: WAG-PONO26-001650 | I15: 1.11 กรอบรูป | K15: 25450
E16: บริษัท อิคาโน่ (ประเทศไทย) จำกัด | H16: WAG-PONO26-001652 | I16: 1.12 โคมไฟ IKEA | K16: 48426
E17: บริษัท เอ็ม-เวิลด์ โลจิสติกส์ (ประเทศไทย) จำกัด | H17: WAG-PONO26-001653 | I17: 1.13 ขนส่ง โคมไฟ IKEA | K17: 290
E18: บริษัท เมมโมรี่ส์ ดีไซน์ แอนด์ พริ้นท์ จำกัด | G18: ORG-PRNO26-016586 | H18: WAG-PONO26-001697 | I18: 1.14 กรอบรูป | K18: 35450
E19: บริษัท อิคาโน่ (ประเทศไทย) จำกัด | H19: WAG-PONO26-001699 | I19: 1.15 โคมไฟ IKEA | K19: 63219.63
E20: บริษัท เอ็ม-เวิลด์ โลจิสติกส์ (ประเทศไทย) จำกัด | H20: WAG-PONO26-001700 | I20: 1.16 ขนส่งโคมไฟ IKEA | K20: 290
E21: ณีรนุช โกทันย์ | G21: ORG-PRNO26-016861 | H21: WAG-PONO26-001705 | I21: 1.17 งานจัดวางของเข้าห้อง | K21: 36000
I22: 2. Curtain
E23: บริษัท บี เรส จำกัด | G23: ORG-PRNO26-000502 | H23: WAG-PONO26-000196 | I23: 2.1 ผ้าม่าน ทึบ-โปร่ง | K23: 1445950
I24: 3. Loose Furniture
E25: บริษัท สมาร์ทพลัส กรุ๊ป จำกัด | G25: ORG-PRNO26-000157 | H25: WAG-PONO26-000221 | I25: 3.1 งานแก้ไขเฟอร์นิเจอร์ | K25: 9000
E26: บริษัท เดอะ ดีไซน์ จำกัด | G26: ORG-PRNO26-004625 | H26: WAG-PONO26-000697 | I26: 3.2 Coffee Table | K26: 153000
E27: บริษัท อรรคพล เฟอร์นิช จำกัด | G27: ORG-PRNO26-007778 | H27: WAG-PONO26-000913 | I27: 3.3 TV Cabinet / Working Table / Working Chair / Side Table / Dining Table | K27: 1902914
E28: บริษัท สมาร์ทพลัส กรุ๊ป จำกัด | G28: ORG-PRNO26-008435 | H28: WAG-PONO26-000957 | I28: 3.4 SOFA | K28: 429000
E29: บริษัท อิคาโน่ (ประเทศไทย) จำกัด | G29: ORG-PRNO26-014528 | H29: WAG-PONO26-001606 | I29: 3.5 Loose Furniture IKEA | K29: 201910
E30: บริษัท เอ็ม-เวิลด์ โลจิสติกส์ (ประเทศไทย) จำกัด | H30: WAG-PONO26-001607 | I30: 3.6 ขนส่ง Loose Furniture IKEA | K30: 16109.35
E31: บริษัท อินเด็กซ์ ลิฟวิ่งมอลล์ จำกัด (มหาชน) | G31: ORG-PRNO26-014551 | H31: WAG-PONO26-001609 | I31: 3.7 Loose Furniture Index | K31: 60225.6
E32: บริษัท เอสบี ดีไซนด์สแควร์ จำกัด | G32: ORG-PRNO26-015042 | H32: WAG-PONO26-001628 | I32: 3.8 Loose Furniture SB | K32: 68953.3
E33: บริษัท เอสบี ดีไซนด์สแควร์ จำกัด | H33: WAG-PONO26-001629 | I33: 3.9 ขนส่ง Loose Furniture SB | K33: 46.73
E34: บริษัท อินเด็กซ์ ลิฟวิ่งมอลล์ จำกัด (มหาชน) | H34: WAG-PONO26-001630 | I34: 3.10 Loose Furniture Index | K34: 68952.92
E35: บริษัท อิคาโน่ (ประเทศไทย) จำกัด | H35: WAG-PONO26-001631 | I35: 3.11 Loose Furniture IKEA | K35: 536757.31
E36: บริษัท เอ็ม-เวิลด์ โลจิสติกส์ (ประเทศไทย) จำกัด | G36: ORG-PRNO26-014528 | H36: WAG-PONO26-001632 | I36: 3.12 ขนส่ง+ประกอบ Loose Furniture IKEA | K36: 44822.9
E37: บริษัท อินเด็กซ์ ลิฟวิ่งมอลล์ จำกัด (มหาชน) | G37: ORG-PRNO26-016586 | H37: WAG-PONO26-001701 | I37: 3.13 Loose Furniture Index | K37: 165440.37
E38: บริษัท อิคาโน่ (ประเทศไทย) จำกัด | H38: WAG-PONO26-001702 | I38: 3.14 Loose Furniture IKEA | K38: 564149.53
E39: บริษัท เอ็ม-เวิลด์ โลจิสติกส์ (ประเทศไทย) จำกัด | H39: WAG-PONO26-001703 | I39: 3.15 ขนส่ง+ประกอบ Loose Furniture IKEA | K39: =39490.65+10150 -> 49640.65
I40: 4. BEDSET
...

Sheet The Origin Bangkae
J1: มูลค่าจัดจ้างซัพ | M1: Cost ประมาณการณ์
B2: โครงการ | C2: Room | D2: Area (sq.m.) | E2: SO | F2: PR | G2: PO | H2: รายการ สั่งซื้อ / สั่งจ้าง | I2: Revenue | J2: จัดจ้างจริง | K2: คงเหลือ (Exc. VAT บาท) | L2: % GP | M2: ประมาณการณ์ | N2: คงเหลือ (Exc. VAT บาท) | O2: % GP | P2: Status | Q2: วันที่ขออนุมัติ | R2: Suppiler
I3: (Ex.Vat) | J3: (Ex.Vat) | M3: (Ex.Vat) | P3: ขออนุัติครั้งนี้ / อนุมัติแล้ว
B4: The Origin Bangkae | C4: Room C310 | H4: 1. Loose Furniture
E5: WAG-SONO23-000456 | F5: ORG-PRNO26-013323 | G5: WAG-PONO26-001563 | H5: 1.1 โต๊ะทานข้าว | I5: =7750/1.07 -> 7242.9907 | J5: =3845/1.07 -> 3593.4579 | K5: =I5-J5 -> 3649.5327 | L5: =K5/I5 -> 0.50387097 | M5: =3845 -> 3845 | N5: =I5-M5 -> 3397.9907 | O5: =N5/I5 -> 0.46914194 | P5: ขออนุมัติแล้ว | Q5: 46209
H6: 1.2 ค่าขนส่ง | I6: 0 | J6: =500/1.07 -> 467.28972 | K6: =I6-J6 -> -467.28972 | L6: =K6/I6 -> #DIV/0! | M6: 500 | N6: =I6-M6 -> -500 | O6: =N6/I6 -> #DIV/0!
B19: =B4 -> The Origin Bangkae | C19: =C4 -> Room C310 | D19: =SUM(D4:D18) -> 0 | H19: TOTAL | I19: =SUM(I4:I18) -> 7242.9907 | J19: =SUM(J4:J18) -> 4060.7477 | K19: =I19-J19 -> 3182.243 | L19: =K19/I19 -> 0.43935484 | M19: =SUM(M4:M18) -> 4345 | N19: =I19-M19 -> 2897.9907 | O19: =N19/I19 -> 0.40010968
B21: The Origin Bangkae | C21: Room A202 | H21: 1. Loose Furniture
E22: WAG-SONO26-000060 | F22: ORG-PRNO26-013245 | G22: WAG-PONO26-001503 | H22: 1.1 โต๊ะกลาง | I22: =5000/1.07 -> 4672.8972 | J22: 2200 | K22: =I22-J22 -> 2472.8972 | L22: =K22/I22 -> 0.5292 | M22: 2200 | N22: =I22-M22 -> 2472.8972 | O22: =N22/I22 -> 0.5292 | P22: ขออนุมัติแล้ว | Q22: 46209
B36: =B21 -> The Origin Bangkae | C36: =C21 -> Room A202 | D36: =SUM(D21:D35) -> 0 | H36: TOTAL | I36: =SUM(I21:I35) -> 4672.8972 | J36: =SUM(J21:J35) -> 2200 | K36: =I36-J36 -> 2472.8972 | L36: =K36/I36 -> 0.5292 | M36: =SUM(M21:M35) -> 2200 | N36: =I36-M36 -> 2472.8972 | O36: =N36/I36 -> 0.5292
B38: The Origin Bangkae | H38: 1. Loose Furniture
B53: =B38 -> The Origin Bangkae | C53: =C38 | D53: =SUM(D38:D52) -> 0 | H53: TOTAL | I53: =SUM(I38:I52) -> 0 | J53: =SUM(J38:J52) -> 0 | K53: =I53-J53 -> 0 | L53: =K53/I53 -> #DIV/0! | M53: =SUM(M38:M52) -> 0 | N53: =I53-M53 -> 0 | O53: =N53/I53 -> #DIV/0!
B55: The Origin Bangkae | H55: 1. Loose Furniture
B70: =B55 -> The Origin Bangkae | C70: =C55 | D70: =SUM(D55:D69) -> 0 | H70: TOTAL | I70: =SUM(I55:I69) -> 0 | J70: =SUM(J55:J69) -> 0 | K70: =I70-J70 -> 0 | L70: =K70/I70 -> #DIV/0! | M70: =SUM(M55:M69) -> 0 | N70: =I70-M70 -> 0 | O70: =N70/I70 -> #DIV/0!

Sheet The Origin Kathu - Patong
J1: มูลค่าจัดจ้างซัพ | M1: Cost ประมาณการณ์
B2: โครงการ | C2: Room | D2: Area (sq.m.) | E2: SO | F2: PR | G2: PO | H2: รายการ สั่งซื้อ / สั่งจ้าง | I2: Revenue | J2: จัดจ้างจริง | K2: คงเหลือ (Exc. VAT บาท) | L2: % GP | M2: ประมาณการณ์ | N2: คงเหลือ (Exc. VAT บาท) | O2: % GP | P2: Status | Q2: วันที่ขออนุมัติ | R2: Suppiler
I3: (Ex.Vat) | J3: (Ex.Vat) | M3: (Ex.Vat) | P3: ขออนุัติครั้งนี้ / อนุมัติแล้ว
B4: The Origin Kathu - Patong | C4: Room B418 | D4: 28.75 sq.m | E4: WAG-SONO26-000328 | F4: ORG-PRNO26-014838 | G4: WAG-PONO26-001634 | H4: 1. Mattress | R4: บริษัท ฮิลดิ้ง แอนเดอร์ส (ประเทศไทย) จำกัด
H5: 1.1 ฟูก 5 ฟุต | I5: =8000/1.07 -> 7476.6355 | J5: 4500 | K5: =I5-J5 -> 2976.6355 | L5: =K5/I5 -> 0.398125 | M5: =4000+500 -> 4500 | N5: =I5-M5 -> 2976.6355 | O5: =N5/I5 -> 0.398125 | P5: ขออนุมัติแล้ว | Q5: 46227
H6: 1.2 BEDSEET 5 ฟุต | I6: =3000/1.07 -> 2803.7383 | J6: 2240 | K6: =I6-J6 -> 563.73832 | L6: =K6/I6 -> 0.20106667 | M6: 2755 | N6: =I5:I6-M6 -> 48.738318 | O6: =N6/I6 -> 0.017383333
G7: WAG-PONO26-001635 | H7: 2. Curtain | R7: นาย วัฒน์ธรกรณ์ รุ่งพรทวีวัฒน์
H8: 2.1 Curtain Bed Room ทึบ-โปร่ง | I8: =17640/1.07 -> 16485.981 | J8: 7200 | K8: =I8-J8 -> 9285.9813 | L8: =K8/I8 -> 0.56326531 | M8: 8500 | N8: =I8-M8 -> 7985.9813 | O8: =N8/I8 -> 0.48441043
H9: 2.2 ค่าติดตั้ง | I9: 0 | J9: 1500 | K9: =I9-J9 -> -1500 | L9: =K9/I9 -> #DIV/0! | M9: 1500 | N9: =I9-M9 -> -1500 | O9: =N9/I9 -> #DIV/0!
H10: ส่วนลด | I10: =-3000/1.07 -> -2803.7383 | J10: -200
B20: =B4 -> The Origin Kathu - Patong | C20: =C4 -> Room B418 | D20: =SUM(D4:D19) -> 0 | H20: TOTAL | I20: =SUM(I4:I19) -> 23962.617 | J20: =SUM(J4:J19) -> 15240 | K20: =I20-J20 -> 8722.6168 | L20: =K20/I20 -> 0.36400936 | M20: =SUM(M4:M19) -> 17255 | N20: =I20-M20 -> 6707.6168 | O20: =N20/I20 -> 0.27992005

Sheet The Origin Phahol 57
J1: มูลค่าจัดจ้างซัพ | M1: Cost ประมาณการณ์
B2: โครงการ | C2: Room | D2: Area (sq.m.) | E2: SO | F2: PR | G2: PO | H2: รายการ สั่งซื้อ / สั่งจ้าง | I2: Revenue | J2: จัดจ้างจริง | K2: คงเหลือ (Exc. VAT บาท) | L2: % GP | M2: ประมาณการณ์ | N2: คงเหลือ (Exc. VAT บาท) | O2: % GP | P2: Status | Q2: วันที่ขออนุมัติ | R2: Suppiler
I3: (Ex.Vat) | J3: (Ex.Vat) | M3: (Ex.Vat) | P3: ขออนุัติครั้งนี้ / อนุมัติแล้ว
B4: The Origin Phahol 57 | C4: Room A402 | D4: 28 sq.m | H4: 1. Curtain
H5: 1.1 ผ้าม่านจีบ ทึบ-โปร่ง ห้องนอน | I5: =13200/1.07 -> 12336.449 | M5: 7500 | N5: =I5-M5 -> 4836.4486 | O5: =N5/I5 -> 0.39204545
H6: ส่วนลด
B16: =B4 -> The Origin Phahol 57 | C16: =C4 -> Room A402 | D16: =SUM(D4:D15) -> 0 | H16: TOTAL | I16: =SUM(I4:I15) -> 12336.449 | J16: =SUM(J4:J15) -> 0 | K16: =I16-J16 -> 12336.449 | L16: =K16/I16 -> 1 | M16: =SUM(M4:M15) -> 7500 | N16: =I16-M16 -> 4836.4486 | O16: =N16/I16 -> 0.39204545
B18: The Origin Phahol 57 | C18: Room B720 | H18: 1. Curtain
H19: 1.1 ผ้าม่านจีบ ทึบ ห้องนอน | I19: =10000/1.07 -> 9345.7944 | M19: 5000 | N19: =I19-M19 -> 4345.7944 | O19: =N19/I19 -> 0.465
H20: ส่วนลด
B30: =B18 -> The Origin Phahol 57 | C30: =C18 -> Room B720 | D30: =SUM(D18:D29) -> 0 | H30: TOTAL | I30: =SUM(I18:I29) -> 9345.7944 | J30: =SUM(J18:J29) -> 0 | K30: =I30-J30 -> 9345.7944 | L30: =K30/I30 -> 1 | M30: =SUM(M18:M29) -> 5000 | N30: =I30-M30 -> 4345.7944 | O30: =N30/I30 -> 0.465

Sheet Knightsbridge Space Sukhumvit -
J1: มูลค่าจัดจ้างซัพ | M1: Cost ประมาณการณ์
B2: โครงการ | C2: Room | D2: Area (sq.m.) | E2: SO | F2: PR | G2: PO | H2: รายการ สั่งซื้อ / สั่งจ้าง | I2: Revenue | J2: จัดจ้างจริง | K2: คงเหลือ (Exc. VAT บาท) | L2: % GP | M2: ประมาณการณ์ | N2: คงเหลือ (Exc. VAT บาท) | O2: % GP | P2: Status | Q2: วันที่ขออนุมัติ | R2: Suppiler
I3: (Ex.Vat) | J3: (Ex.Vat) | M3: (Ex.Vat) | P3: ขออนุัติครั้งนี้ / อนุมัติแล้ว
B4: Knightsbridge Space Sukhumvit - Rama4 | C4: Room 1009 | H4: 1. Curtain & Wallpaper
H5: 1.1 ม่าน ทึบโปร่ง เพดานสูงชั้นล่าง | I5: =24000/1.07 -> 22429.907 | M5: 15000 | N5: =I5-M5 -> 7429.9065 | O5: =N5/I5 -> 0.33125
H6: 1.2 ม่านโปร่งชั้นลอย | I6: =10400/1.07 -> 9719.6262 | M6: 8000 | N6: =I6-M6 -> 1719.6262 | O6: =N6/I6 -> 0.17692308
H7: 1.3 วอลเปเปอร์รอบห้อง 2 สี | I7: =23100/1.07 -> 21588.785 | M7: 14000 | N7: =I7-M7 -> 7588.785 | O7: =N7/I7 -> 0.35151515
H8: 2. Built in
H9: 2.1 หัวเตียง ปิดลามิเนตลายไม้สีเข้ม + ซ่อนไฟLED หัวเตียง | I9: =30560/1.07 -> 28560.748 | M9: 19000 | N9: =I9-M9 -> 9560.7477 | O9: =N9/I9 -> 0.33475131
H10: 3. Lighting
H11: 3.1 แชนเดอเรีย | I11: =24900/1.07 -> 23271.028 | M11: 17000 | N11: =I11-M11 -> 6271.028 | O11: =N11/I11 -> 0.26947791
H12: 3.2 ค่าติดตั้ง | I12: 0 | M12: 0 | N12: =I12-M12 -> 0 | O12: =N12/I12 -> #DIV/0!
H13: 4. Mattress
H14: 4.1 ที่นอน 5 ฟุต | I14: =8000/1.07 -> 7476.6355 | M14: 4500 | N14: =I14-M14 -> 2976.6355 | O14: =N14/I14 -> 0.398125
H15: 5. Loose Furniture
H16: 5.1 โซฟา 3 ที่นั่ง 176 cm x 88 cm x 83 cm | I16: =13900/1.07 -> 12990.654 | M16: 9480 | N16: =I16-M16 -> 3510.6542 | O16: =N16/I16 -> 0.2702446
H17: 5.2 โต๊ะอาหาร | I17: =4000/1.07 -> 3738.3178 | M17: 2900 | N17: =I17-M17 -> 838.31776 | O17: =N17/I17 -> 0.22425
H18: 5.3 เก้าอี้ 2 ตัว | I18: =5980/1.07 -> 5588.785 | M18: 4686 | N18: =I18-M18 -> 902.78505 | O18: =N18/I18 -> 0.16153512
H19: 5.4 โต๊ะกลางแบบ ยกได้ | I19: =7660/1.07 -> 7158.8785 | M19: 5005 | N19: =I19-M19 -> 2153.8785 | O19: =N19/I19 -> 0.30086815
H20: 5.5 กระจกจกเงาติดผนังทางขึ้นบันได 65x150 cm. | I20: =4900/1.07 -> 4579.4393 | M20: 2100 | N20: =I20-M20 -> 2479.4393 | O20: =N20/I20 -> 0.54142857
H21: 5.6 ชั้นวางติดผนัง 2 ชั้น (ข้างโซฟา) | I21: =3200/1.07 -> 2990.6542 | M21: 1000 | N21: =I21-M21 -> 1990.6542 | O21: =N21/I21 -> 0.665625
B22: =B4 -> Knightsbridge Space Sukhumvit - Rama4 | C22: =C4 -> Room 1009 | D22: =SUM(D4:D21) -> 0 | H22: TOTAL | I22: =SUM(I4:I21) -> 150093.46 | J22: =SUM(J4:J21) -> 0 | K22: =I22-J22 -> 150093.46 | L22: =K22/I22 -> 1 | M22: =SUM(M4:M21) -> 102671 | N22: =I22-M22 -> 47422.458 | O22: =N22/I22 -> 0.31595286

Sheet Origin Play Bangsaen
J1: มูลค่าจัดจ้างซัพ | M1: Cost ประมาณการณ์
B2: โครงการ | C2: Room | D2: Area (sq.m.) | E2: SO | F2: PR | G2: PO | H2: รายการ สั่งซื้อ / สั่งจ้าง | I2: Revenue | J2: จัดจ้างจริง | K2: คงเหลือ (Exc. VAT บาท) | L2: % GP | M2: ประมาณการณ์ | N2: คงเหลือ (Exc. VAT บาท) | O2: % GP | P2: Status | Q2: วันที่ขออนุมัติ | R2: Suppiler
I3: (Ex.Vat) | J3: (Ex.Vat) | M3: (Ex.Vat) | P3: ขออนุัติครั้งนี้ / อนุมัติแล้ว
